[2025-09-09 23:13:23,458: INFO : main: Welcome to custom logger DS]
[2025-09-09 23:13:23,459: INFO : main: >>>>>>>>>>>>>>> Stage Data Ingestion Stage Started  <<<<<<<<<<<<<]
[2025-09-09 23:13:23,461: INFO : common: yaml file: config\config.yaml loaded sucessfully]
[2025-09-09 23:13:23,462: INFO : common: yaml file: params.yaml loaded sucessfully]
[2025-09-09 23:13:23,464: INFO : common: yaml file: schema.yaml loaded sucessfully]
[2025-09-09 23:13:23,465: INFO : common: created directory at path :artifacts]
[2025-09-09 23:13:23,465: INFO : common: created directory at path :artifacts/data_validation]
[2025-09-09 23:13:23,466: ERROR : main: "'ConfigBox' object has no attribute 'source_url'"]
Traceback (most recent call last):
  File "box\\box.py", line 594, in box.box.Box.__getitem__
KeyError: 'source_url'

The above exception was the direct cause of the following exception:

Traceback (most recent call last):
  File "box\\box.py", line 633, in box.box.Box.__getattr__
  File "box\\box.py", line 621, in box.box.Box.__getitem__
box.exceptions.BoxKeyError: "'source_url'"

During handling of the above exception, another exception occurred:

Traceback (most recent call last):
  File "box\\box.py", line 635, in box.box.Box.__getattr__
AttributeError: 'ConfigBox' object has no attribute 'source_url'

The above exception was the direct cause of the following exception:

Traceback (most recent call last):
  File "box\\config_box.py", line 29, in box.config_box.ConfigBox.__getattr__
  File "box\\box.py", line 649, in box.box.Box.__getattr__
box.exceptions.BoxKeyError: "'ConfigBox' object has no attribute 'source_url'"

During handling of the above exception, another exception occurred:

Traceback (most recent call last):
  File "box\\box.py", line 594, in box.box.Box.__getitem__
KeyError: 'source_url'

The above exception was the direct cause of the following exception:

Traceback (most recent call last):
  File "box\\box.py", line 633, in box.box.Box.__getattr__
  File "box\\box.py", line 621, in box.box.Box.__getitem__
box.exceptions.BoxKeyError: "'source_url'"

During handling of the above exception, another exception occurred:

Traceback (most recent call last):
  File "box\\box.py", line 635, in box.box.Box.__getattr__
AttributeError: 'ConfigBox' object has no attribute 'source_url'

The above exception was the direct cause of the following exception:

Traceback (most recent call last):
  File "D:\DE\ML OPs\DSusingMLOps\main.py", line 12, in <module>
    obj.initiate_Data_ingestion()
    ~~~~~~~~~~~~~~~~~~~~~~~~~~~^^
  File "D:\DE\ML OPs\DSusingMLOps\src\datascience\pipeline\data_ingestion_pipeline.py", line 14, in initiate_Data_ingestion
    data_ingestion_config=config.get_data_ingestion_config()
  File "D:\DE\ML OPs\DSusingMLOps\src\datascience\config\configuration.py", line 23, in get_data_ingestion_config
    source_url=config.source_url,
               ^^^^^^^^^^^^^^^^^
  File "box\\config_box.py", line 31, in box.config_box.ConfigBox.__getattr__
  File "box\\box.py", line 649, in box.box.Box.__getattr__
box.exceptions.BoxKeyError: "'ConfigBox' object has no attribute 'source_url'"
[2025-09-09 23:13:40,377: INFO : main: Welcome to custom logger DS]
[2025-09-09 23:13:40,377: INFO : main: >>>>>>>>>>>>>>> Stage Data Ingestion Stage Started  <<<<<<<<<<<<<]
[2025-09-09 23:13:40,379: INFO : common: yaml file: config\config.yaml loaded sucessfully]
[2025-09-09 23:13:40,380: INFO : common: yaml file: params.yaml loaded sucessfully]
[2025-09-09 23:13:40,380: INFO : common: yaml file: schema.yaml loaded sucessfully]
[2025-09-09 23:13:40,381: INFO : common: created directory at path :artifacts]
[2025-09-09 23:13:40,381: INFO : common: created directory at path :artifacts/data_ingestion]
[2025-09-09 23:13:41,339: INFO : data_ingestion: artifacts/data_ingestion/data.zip download! with following info: 
Connection: close
Content-Length: 23329
Cache-Control: max-age=300
Content-Security-Policy: default-src 'none'; style-src 'unsafe-inline'; sandbox
Content-Type: application/zip
ETag: "c69888a4ae59bc5a893392785a938ccd4937981c06ba8a9d6a21aa52b4ab5b6e"
Strict-Transport-Security: max-age=31536000
X-Content-Type-Options: nosniff
X-Frame-Options: deny
X-XSS-Protection: 1; mode=block
X-GitHub-Request-Id: E751:394C7E:9119E:BB4EE:68C0E65A
Accept-Ranges: bytes
Date: Wed, 10 Sep 2025 03:13:41 GMT
Via: 1.1 varnish
X-Served-By: cache-yyz4577-YYZ
X-Cache: HIT
X-Cache-Hits: 0
X-Timer: S1757474021.211756,VS0,VE34
Vary: Authorization,Accept-Encoding
Access-Control-Allow-Origin: *
Cross-Origin-Resource-Policy: cross-origin
X-Fastly-Request-ID: 856774439d48f9c8562451cf78e1ce7aedc26f34
Expires: Wed, 10 Sep 2025 03:18:41 GMT
Source-Age: 0

]
[2025-09-09 23:13:41,354: INFO : main: >>>>>> Stage Data Ingestion Stage Completed  <<<<<<<]
[2025-09-09 23:40:46,325: INFO : common: yaml file: config\config.yaml loaded sucessfully]
[2025-09-09 23:40:46,327: INFO : common: yaml file: params.yaml loaded sucessfully]
[2025-09-09 23:40:46,330: INFO : common: yaml file: schema.yaml loaded sucessfully]
[2025-09-09 23:40:46,332: INFO : common: created directory at path :artifacts]
[2025-09-09 23:40:46,334: INFO : common: created directory at path :artifacts/data_validation]
[2025-09-09 23:41:11,069: INFO : common: yaml file: config\config.yaml loaded sucessfully]
[2025-09-09 23:41:11,071: INFO : common: yaml file: params.yaml loaded sucessfully]
[2025-09-09 23:41:11,075: INFO : common: yaml file: schema.yaml loaded sucessfully]
[2025-09-09 23:41:11,077: INFO : common: created directory at path :artifacts]
[2025-09-09 23:41:11,078: INFO : common: created directory at path :artifacts/data_validation]
[2025-09-09 23:41:39,913: INFO : common: yaml file: config\config.yaml loaded sucessfully]
[2025-09-09 23:41:39,914: INFO : common: yaml file: params.yaml loaded sucessfully]
[2025-09-09 23:41:39,917: INFO : common: yaml file: schema.yaml loaded sucessfully]
[2025-09-09 23:41:39,919: INFO : common: created directory at path :artifacts]
[2025-09-09 23:41:39,920: INFO : common: created directory at path :artifacts/data_validation]
[2025-09-09 23:41:59,140: INFO : common: yaml file: config\config.yaml loaded sucessfully]
[2025-09-09 23:41:59,142: INFO : common: yaml file: params.yaml loaded sucessfully]
[2025-09-09 23:41:59,144: INFO : common: yaml file: schema.yaml loaded sucessfully]
[2025-09-09 23:41:59,145: INFO : common: created directory at path :artifacts]
[2025-09-09 23:41:59,146: INFO : common: created directory at path :artifacts/data_validation]
[2025-09-09 23:42:21,620: INFO : common: yaml file: config\config.yaml loaded sucessfully]
[2025-09-09 23:42:21,622: INFO : common: yaml file: params.yaml loaded sucessfully]
[2025-09-09 23:42:21,625: INFO : common: yaml file: schema.yaml loaded sucessfully]
[2025-09-09 23:42:21,627: INFO : common: created directory at path :artifacts]
[2025-09-09 23:42:21,629: INFO : common: created directory at path :artifacts/data_validation]
[2025-09-09 23:42:49,580: INFO : common: yaml file: config\config.yaml loaded sucessfully]
[2025-09-09 23:42:49,582: INFO : common: yaml file: params.yaml loaded sucessfully]
[2025-09-09 23:42:49,585: INFO : common: yaml file: schema.yaml loaded sucessfully]
[2025-09-09 23:42:49,587: INFO : common: created directory at path :artifacts]
[2025-09-09 23:42:49,588: INFO : common: created directory at path :artifacts/data_validation]
[2025-09-09 23:44:00,065: INFO : common: yaml file: config\config.yaml loaded sucessfully]
[2025-09-09 23:44:00,067: INFO : common: yaml file: params.yaml loaded sucessfully]
[2025-09-09 23:44:00,069: INFO : common: yaml file: schema.yaml loaded sucessfully]
[2025-09-09 23:44:00,071: INFO : common: created directory at path :artifacts]
[2025-09-09 23:44:00,073: INFO : common: created directory at path :artifacts/data_validation]
[2025-09-09 23:44:42,414: INFO : common: yaml file: config\config.yaml loaded sucessfully]
[2025-09-09 23:44:42,416: INFO : common: yaml file: params.yaml loaded sucessfully]
[2025-09-09 23:44:42,419: INFO : common: yaml file: schema.yaml loaded sucessfully]
[2025-09-09 23:44:42,420: INFO : common: created directory at path :artifacts]
[2025-09-09 23:44:42,421: INFO : common: created directory at path :artifacts/data_validation]
[2025-09-09 23:45:10,147: INFO : common: yaml file: config\config.yaml loaded sucessfully]
[2025-09-09 23:45:10,149: INFO : common: yaml file: params.yaml loaded sucessfully]
[2025-09-09 23:45:10,152: INFO : common: yaml file: schema.yaml loaded sucessfully]
[2025-09-09 23:45:10,154: INFO : common: created directory at path :artifacts]
[2025-09-09 23:45:10,155: INFO : common: created directory at path :artifacts/data_validation]
[2025-09-09 23:45:27,740: INFO : common: yaml file: config\config.yaml loaded sucessfully]
[2025-09-09 23:45:27,741: INFO : common: yaml file: params.yaml loaded sucessfully]
[2025-09-09 23:45:27,745: INFO : common: yaml file: schema.yaml loaded sucessfully]
[2025-09-09 23:45:27,746: INFO : common: created directory at path :artifacts]
[2025-09-09 23:45:27,747: INFO : common: created directory at path :artifacts/data_validation]
[2025-09-09 23:57:16,504: INFO : main: Welcome to custom logger DS]
[2025-09-09 23:57:16,505: INFO : main: >>>>>>>>>>>>>>> Stage Data Ingestion Stage Started  <<<<<<<<<<<<<]
[2025-09-09 23:57:16,506: INFO : common: yaml file: config\config.yaml loaded sucessfully]
[2025-09-09 23:57:16,507: INFO : common: yaml file: params.yaml loaded sucessfully]
[2025-09-09 23:57:16,508: INFO : common: yaml file: schema.yaml loaded sucessfully]
[2025-09-09 23:57:16,509: INFO : common: created directory at path :artifacts]
[2025-09-09 23:57:16,509: INFO : common: created directory at path :artifacts/data_ingestion]
[2025-09-09 23:57:16,509: INFO : data_ingestion: File already exists]
[2025-09-09 23:57:16,512: INFO : main: >>>>>> Stage Data Ingestion Stage Completed  <<<<<<<]
[2025-09-09 23:57:16,512: INFO : main: >>>>>>>>>>>>>>> Stage Data Validation  Stage Started  <<<<<<<<<<<<<]
[2025-09-09 23:57:16,514: INFO : common: yaml file: config\config.yaml loaded sucessfully]
[2025-09-09 23:57:16,515: INFO : common: yaml file: params.yaml loaded sucessfully]
[2025-09-09 23:57:16,517: INFO : common: yaml file: schema.yaml loaded sucessfully]
[2025-09-09 23:57:16,518: INFO : common: created directory at path :artifacts]
[2025-09-09 23:57:16,519: INFO : common: created directory at path :artifacts/data_ingestion]
[2025-09-09 23:57:16,519: ERROR : main: 'DataIngestionConfig' object has no attribute 'unzip_data_dir']
Traceback (most recent call last):
  File "D:\DE\ML OPs\DSusingMLOps\main.py", line 24, in <module>
    obj.initiate_Data_Validation()
    ~~~~~~~~~~~~~~~~~~~~~~~~~~~~^^
  File "D:\DE\ML OPs\DSusingMLOps\src\datascience\pipeline\data_validation_pipeline.py", line 16, in initiate_Data_Validation
    data_validation.validate_all_columns()
    ~~~~~~~~~~~~~~~~~~~~~~~~~~~~~~~~~~~~^^
  File "D:\DE\ML OPs\DSusingMLOps\src\datascience\components\data_validation.py", line 11, in validate_all_columns
    data = pd.read_csv(self.config.unzip_data_dir)
                       ^^^^^^^^^^^^^^^^^^^^^^^^^^
AttributeError: 'DataIngestionConfig' object has no attribute 'unzip_data_dir'
[2025-09-09 23:58:14,210: INFO : common: yaml file: config\config.yaml loaded sucessfully]
[2025-09-09 23:58:14,212: INFO : common: yaml file: params.yaml loaded sucessfully]
[2025-09-09 23:58:14,215: INFO : common: yaml file: schema.yaml loaded sucessfully]
[2025-09-09 23:58:14,217: INFO : common: created directory at path :artifacts]
[2025-09-09 23:58:14,219: INFO : common: created directory at path :artifacts/data_validation]
[2025-09-10 00:00:11,768: INFO : main: Welcome to custom logger DS]
[2025-09-10 00:00:11,768: INFO : main: >>>>>>>>>>>>>>> Stage Data Ingestion Stage Started  <<<<<<<<<<<<<]
[2025-09-10 00:00:11,769: INFO : common: yaml file: config\config.yaml loaded sucessfully]
[2025-09-10 00:00:11,770: INFO : common: yaml file: params.yaml loaded sucessfully]
[2025-09-10 00:00:11,772: INFO : common: yaml file: schema.yaml loaded sucessfully]
[2025-09-10 00:00:11,772: INFO : common: created directory at path :artifacts]
[2025-09-10 00:00:11,772: INFO : common: created directory at path :artifacts/data_ingestion]
[2025-09-10 00:00:11,773: INFO : data_ingestion: File already exists]
[2025-09-10 00:00:11,775: INFO : main: >>>>>> Stage Data Ingestion Stage Completed  <<<<<<<]
[2025-09-10 00:00:11,775: INFO : main: >>>>>>>>>>>>>>> Stage Data Validation  Stage Started  <<<<<<<<<<<<<]
[2025-09-10 00:00:11,777: INFO : common: yaml file: config\config.yaml loaded sucessfully]
[2025-09-10 00:00:11,778: INFO : common: yaml file: params.yaml loaded sucessfully]
[2025-09-10 00:00:11,780: INFO : common: yaml file: schema.yaml loaded sucessfully]
[2025-09-10 00:00:11,781: INFO : common: created directory at path :artifacts]
[2025-09-10 00:00:11,781: INFO : common: created directory at path :artifacts/data_ingestion]
[2025-09-10 00:00:11,781: ERROR : main: 'DataIngestionConfig' object has no attribute 'unzip_data_dir']
Traceback (most recent call last):
  File "D:\DE\ML OPs\DSusingMLOps\main.py", line 24, in <module>
    obj.initiate_Data_Validation()
    ~~~~~~~~~~~~~~~~~~~~~~~~~~~~^^
  File "D:\DE\ML OPs\DSusingMLOps\src\datascience\pipeline\data_validation_pipeline.py", line 16, in initiate_Data_Validation
    data_validation.validate_all_columns()
    ~~~~~~~~~~~~~~~~~~~~~~~~~~~~~~~~~~~~^^
  File "D:\DE\ML OPs\DSusingMLOps\src\datascience\components\data_validation.py", line 11, in validate_all_columns
    data = pd.read_csv(self.config.unzip_data_dir)
                       ^^^^^^^^^^^^^^^^^^^^^^^^^^
AttributeError: 'DataIngestionConfig' object has no attribute 'unzip_data_dir'
[2025-09-10 00:02:28,912: INFO : main: Welcome to custom logger DS]
[2025-09-10 00:02:28,912: INFO : main: >>>>>>>>>>>>>>> Stage Data Ingestion Stage Started  <<<<<<<<<<<<<]
[2025-09-10 00:02:28,914: INFO : common: yaml file: config\config.yaml loaded sucessfully]
[2025-09-10 00:02:28,915: INFO : common: yaml file: params.yaml loaded sucessfully]
[2025-09-10 00:02:28,917: INFO : common: yaml file: schema.yaml loaded sucessfully]
[2025-09-10 00:02:28,917: INFO : common: created directory at path :artifacts]
[2025-09-10 00:02:28,917: INFO : common: created directory at path :artifacts/data_ingestion]
[2025-09-10 00:02:28,918: INFO : data_ingestion: File already exists]
[2025-09-10 00:02:28,920: INFO : main: >>>>>> Stage Data Ingestion Stage Completed  <<<<<<<]
[2025-09-10 00:02:28,921: INFO : main: >>>>>>>>>>>>>>> Stage Data Validation  Stage Started  <<<<<<<<<<<<<]
[2025-09-10 00:02:28,922: INFO : common: yaml file: config\config.yaml loaded sucessfully]
[2025-09-10 00:02:28,923: INFO : common: yaml file: params.yaml loaded sucessfully]
[2025-09-10 00:02:28,925: INFO : common: yaml file: schema.yaml loaded sucessfully]
[2025-09-10 00:02:28,926: INFO : common: created directory at path :artifacts]
[2025-09-10 00:02:28,926: INFO : common: created directory at path :artifacts/data_ingestion]
[2025-09-10 00:02:28,926: ERROR : main: 'DataIngestionConfig' object has no attribute 'unzip_data_dir']
Traceback (most recent call last):
  File "D:\DE\ML OPs\DSusingMLOps\main.py", line 24, in <module>
    obj.initiate_Data_Validation()
    ~~~~~~~~~~~~~~~~~~~~~~~~~~~~^^
  File "D:\DE\ML OPs\DSusingMLOps\src\datascience\pipeline\data_validation_pipeline.py", line 16, in initiate_Data_Validation
    data_validation.validate_all_columns()
    ~~~~~~~~~~~~~~~~~~~~~~~~~~~~~~~~~~~~^^
  File "D:\DE\ML OPs\DSusingMLOps\src\datascience\components\data_validation.py", line 11, in validate_all_columns
    data = pd.read_csv(self.config.unzip_data_dir)
                       ^^^^^^^^^^^^^^^^^^^^^^^^^^
AttributeError: 'DataIngestionConfig' object has no attribute 'unzip_data_dir'
[2025-09-10 00:04:07,696: INFO : main: Welcome to custom logger DS]
[2025-09-10 00:04:07,697: INFO : main: >>>>>>>>>>>>>>> Stage Data Ingestion Stage Started  <<<<<<<<<<<<<]
[2025-09-10 00:04:07,699: INFO : common: yaml file: config\config.yaml loaded sucessfully]
[2025-09-10 00:04:07,700: INFO : common: yaml file: params.yaml loaded sucessfully]
[2025-09-10 00:04:07,702: INFO : common: yaml file: schema.yaml loaded sucessfully]
[2025-09-10 00:04:07,704: INFO : common: created directory at path :artifacts]
[2025-09-10 00:04:07,705: INFO : common: created directory at path :artifacts/data_ingestion]
[2025-09-10 00:04:07,705: INFO : data_ingestion: File already exists]
[2025-09-10 00:04:07,709: INFO : main: >>>>>> Stage Data Ingestion Stage Completed  <<<<<<<]
[2025-09-10 00:04:07,709: INFO : main: >>>>>>>>>>>>>>> Stage Data Validation  Stage Started  <<<<<<<<<<<<<]
[2025-09-10 00:04:07,712: INFO : common: yaml file: config\config.yaml loaded sucessfully]
[2025-09-10 00:04:07,713: INFO : common: yaml file: params.yaml loaded sucessfully]
[2025-09-10 00:04:07,715: INFO : common: yaml file: schema.yaml loaded sucessfully]
[2025-09-10 00:04:07,717: INFO : common: created directory at path :artifacts]
[2025-09-10 00:04:07,718: INFO : common: created directory at path :artifacts/data_ingestion]
[2025-09-10 00:04:07,719: ERROR : main: 'DataIngestionConfig' object has no attribute 'unzip_data_dir']
Traceback (most recent call last):
  File "D:\DE\ML OPs\DSusingMLOps\main.py", line 24, in <module>
    obj.initiate_Data_Validation()
    ~~~~~~~~~~~~~~~~~~~~~~~~~~~~^^
  File "D:\DE\ML OPs\DSusingMLOps\src\datascience\pipeline\data_validation_pipeline.py", line 16, in initiate_Data_Validation
    data_validation.validate_all_columns()
    ~~~~~~~~~~~~~~~~~~~~~~~~~~~~~~~~~~~~^^
  File "D:\DE\ML OPs\DSusingMLOps\src\datascience\components\data_validation.py", line 11, in validate_all_columns
    data = pd.read_csv(self.config.unzip_data_dir)
                       ^^^^^^^^^^^^^^^^^^^^^^^^^^
AttributeError: 'DataIngestionConfig' object has no attribute 'unzip_data_dir'
[2025-09-10 00:07:22,119: INFO : main: Welcome to custom logger DS]
[2025-09-10 00:07:22,119: INFO : main: >>>>>>>>>>>>>>> Stage Data Ingestion Stage Started  <<<<<<<<<<<<<]
[2025-09-10 00:07:22,121: INFO : common: yaml file: config\config.yaml loaded sucessfully]
[2025-09-10 00:07:22,121: INFO : common: yaml file: params.yaml loaded sucessfully]
[2025-09-10 00:07:22,123: INFO : common: yaml file: schema.yaml loaded sucessfully]
[2025-09-10 00:07:22,124: INFO : common: created directory at path :artifacts]
[2025-09-10 00:07:22,124: INFO : common: created directory at path :artifacts/data_ingestion]
[2025-09-10 00:07:22,124: INFO : data_ingestion: File already exists]
[2025-09-10 00:07:22,127: INFO : main: >>>>>> Stage Data Ingestion Stage Completed  <<<<<<<]
[2025-09-10 00:07:22,127: INFO : main: >>>>>>>>>>>>>>> Stage Data Validation  Stage Started  <<<<<<<<<<<<<]
[2025-09-10 00:07:22,129: INFO : common: yaml file: config\config.yaml loaded sucessfully]
[2025-09-10 00:07:22,130: INFO : common: yaml file: params.yaml loaded sucessfully]
[2025-09-10 00:07:22,132: INFO : common: yaml file: schema.yaml loaded sucessfully]
[2025-09-10 00:07:22,132: INFO : common: created directory at path :artifacts]
[2025-09-10 00:07:22,133: INFO : common: created directory at path :artifacts/data_ingestion]
[2025-09-10 00:07:22,133: ERROR : main: 'DataIngestionConfig' object has no attribute 'unzip_data_dir']
Traceback (most recent call last):
  File "D:\DE\ML OPs\DSusingMLOps\main.py", line 24, in <module>
    obj.initiate_Data_Validation()
    ~~~~~~~~~~~~~~~~~~~~~~~~~~~~^^
  File "D:\DE\ML OPs\DSusingMLOps\src\datascience\pipeline\data_validation_pipeline.py", line 16, in initiate_Data_Validation
    data_validation.validate_all_columns()
    ~~~~~~~~~~~~~~~~~~~~~~~~~~~~~~~~~~~~^^
  File "D:\DE\ML OPs\DSusingMLOps\src\datascience\components\data_validation.py", line 29, in validate_all_columns
    raise e
  File "D:\DE\ML OPs\DSusingMLOps\src\datascience\components\data_validation.py", line 12, in validate_all_columns
    data = pd.read_csv(self.config.unzip_data_dir)
                       ^^^^^^^^^^^^^^^^^^^^^^^^^^
AttributeError: 'DataIngestionConfig' object has no attribute 'unzip_data_dir'
[2025-09-10 00:08:18,599: INFO : main: Welcome to custom logger DS]
[2025-09-10 00:08:18,600: INFO : main: >>>>>>>>>>>>>>> Stage Data Ingestion Stage Started  <<<<<<<<<<<<<]
[2025-09-10 00:08:18,602: INFO : common: yaml file: config\config.yaml loaded sucessfully]
[2025-09-10 00:08:18,603: INFO : common: yaml file: params.yaml loaded sucessfully]
[2025-09-10 00:08:18,605: INFO : common: yaml file: schema.yaml loaded sucessfully]
[2025-09-10 00:08:18,606: INFO : common: created directory at path :artifacts]
[2025-09-10 00:08:18,606: INFO : common: created directory at path :artifacts/data_ingestion]
[2025-09-10 00:08:18,607: INFO : data_ingestion: File already exists]
[2025-09-10 00:08:18,611: INFO : main: >>>>>> Stage Data Ingestion Stage Completed  <<<<<<<]
[2025-09-10 00:08:18,612: INFO : main: >>>>>>>>>>>>>>> Stage Data Validation  Stage Started  <<<<<<<<<<<<<]
[2025-09-10 00:08:18,615: INFO : common: yaml file: config\config.yaml loaded sucessfully]
[2025-09-10 00:08:18,616: INFO : common: yaml file: params.yaml loaded sucessfully]
[2025-09-10 00:08:18,620: INFO : common: yaml file: schema.yaml loaded sucessfully]
[2025-09-10 00:08:18,621: INFO : common: created directory at path :artifacts]
[2025-09-10 00:08:18,623: INFO : common: created directory at path :artifacts/data_validation]
[2025-09-10 00:08:18,665: INFO : main: >>>>>> Stage Data Validation  Stage Completed  <<<<<<<]
[2025-09-12 21:01:01,676: INFO : common: yaml file: config\config.yaml loaded sucessfully]
[2025-09-12 21:01:01,687: INFO : common: yaml file: params.yaml loaded sucessfully]
[2025-09-12 21:01:01,700: INFO : common: yaml file: schema.yaml loaded sucessfully]
[2025-09-12 21:01:01,702: INFO : common: created directory at path :artifacts]
[2025-09-12 21:01:01,704: INFO : common: created directory at path :artifacts/data_transformation]
[2025-09-12 21:01:01,722: ERROR : 980687175: [Errno 13] Permission denied: 'artifacts\\data_transformation']
Traceback (most recent call last):
  File "C:\Users\bibhu\AppData\Local\Temp\ipykernel_24416\980687175.py", line 5, in <module>
    data_transformation.train_test_data_splitting()
    ~~~~~~~~~~~~~~~~~~~~~~~~~~~~~~~~~~~~~~~~~~~~~^^
  File "C:\Users\bibhu\AppData\Local\Temp\ipykernel_24416\45674994.py", line 8, in train_test_data_splitting
    train.to_csv(self.config.root_dir ,"train.csv", index=False)
    ~~~~~~~~~~~~^^^^^^^^^^^^^^^^^^^^^^^^^^^^^^^^^^^^^^^^^^^^^^^^
  File "d:\DE\ML OPs\DSusingMLOps\venv\Lib\site-packages\pandas\util\_decorators.py", line 333, in wrapper
    return func(*args, **kwargs)
  File "d:\DE\ML OPs\DSusingMLOps\venv\Lib\site-packages\pandas\core\generic.py", line 3986, in to_csv
    return DataFrameRenderer(formatter).to_csv(
           ~~~~~~~~~~~~~~~~~~~~~~~~~~~~~~~~~~~^
        path_or_buf,
        ^^^^^^^^^^^^
    ...<14 lines>...
        storage_options=storage_options,
        ^^^^^^^^^^^^^^^^^^^^^^^^^^^^^^^^
    )
    ^
  File "d:\DE\ML OPs\DSusingMLOps\venv\Lib\site-packages\pandas\io\formats\format.py", line 1014, in to_csv
    csv_formatter.save()
    ~~~~~~~~~~~~~~~~~~^^
  File "d:\DE\ML OPs\DSusingMLOps\venv\Lib\site-packages\pandas\io\formats\csvs.py", line 251, in save
    with get_handle(
         ~~~~~~~~~~^
        self.filepath_or_buffer,
        ^^^^^^^^^^^^^^^^^^^^^^^^
    ...<4 lines>...
        storage_options=self.storage_options,
        ^^^^^^^^^^^^^^^^^^^^^^^^^^^^^^^^^^^^^
    ) as handles:
    ^
  File "d:\DE\ML OPs\DSusingMLOps\venv\Lib\site-packages\pandas\io\common.py", line 873, in get_handle
    handle = open(
        handle,
    ...<3 lines>...
        newline="",
    )
PermissionError: [Errno 13] Permission denied: 'artifacts\\data_transformation'
[2025-09-12 21:02:11,058: INFO : common: yaml file: config\config.yaml loaded sucessfully]
[2025-09-12 21:02:11,061: INFO : common: yaml file: params.yaml loaded sucessfully]
[2025-09-12 21:02:11,064: INFO : common: yaml file: schema.yaml loaded sucessfully]
[2025-09-12 21:02:11,066: INFO : common: created directory at path :artifacts]
[2025-09-12 21:02:11,068: INFO : common: created directory at path :artifacts/data_transformation]
[2025-09-12 21:02:11,076: ERROR : 980687175: [Errno 13] Permission denied: 'artifacts\\data_transformation']
Traceback (most recent call last):
  File "C:\Users\bibhu\AppData\Local\Temp\ipykernel_24416\980687175.py", line 5, in <module>
    data_transformation.train_test_data_splitting()
    ~~~~~~~~~~~~~~~~~~~~~~~~~~~~~~~~~~~~~~~~~~~~~^^
  File "C:\Users\bibhu\AppData\Local\Temp\ipykernel_24416\45674994.py", line 8, in train_test_data_splitting
    train.to_csv(self.config.root_dir ,"train.csv", index=False)
    ~~~~~~~~~~~~^^^^^^^^^^^^^^^^^^^^^^^^^^^^^^^^^^^^^^^^^^^^^^^^
  File "d:\DE\ML OPs\DSusingMLOps\venv\Lib\site-packages\pandas\util\_decorators.py", line 333, in wrapper
    return func(*args, **kwargs)
  File "d:\DE\ML OPs\DSusingMLOps\venv\Lib\site-packages\pandas\core\generic.py", line 3986, in to_csv
    return DataFrameRenderer(formatter).to_csv(
           ~~~~~~~~~~~~~~~~~~~~~~~~~~~~~~~~~~~^
        path_or_buf,
        ^^^^^^^^^^^^
    ...<14 lines>...
        storage_options=storage_options,
        ^^^^^^^^^^^^^^^^^^^^^^^^^^^^^^^^
    )
    ^
  File "d:\DE\ML OPs\DSusingMLOps\venv\Lib\site-packages\pandas\io\formats\format.py", line 1014, in to_csv
    csv_formatter.save()
    ~~~~~~~~~~~~~~~~~~^^
  File "d:\DE\ML OPs\DSusingMLOps\venv\Lib\site-packages\pandas\io\formats\csvs.py", line 251, in save
    with get_handle(
         ~~~~~~~~~~^
        self.filepath_or_buffer,
        ^^^^^^^^^^^^^^^^^^^^^^^^
    ...<4 lines>...
        storage_options=self.storage_options,
        ^^^^^^^^^^^^^^^^^^^^^^^^^^^^^^^^^^^^^
    ) as handles:
    ^
  File "d:\DE\ML OPs\DSusingMLOps\venv\Lib\site-packages\pandas\io\common.py", line 873, in get_handle
    handle = open(
        handle,
    ...<3 lines>...
        newline="",
    )
PermissionError: [Errno 13] Permission denied: 'artifacts\\data_transformation'
[2025-09-12 21:05:06,146: INFO : common: yaml file: config\config.yaml loaded sucessfully]
[2025-09-12 21:05:06,149: INFO : common: yaml file: params.yaml loaded sucessfully]
[2025-09-12 21:05:06,153: INFO : common: yaml file: schema.yaml loaded sucessfully]
[2025-09-12 21:05:06,155: INFO : common: created directory at path :artifacts]
[2025-09-12 21:05:06,157: INFO : common: created directory at path :artifacts/data_transformation]
[2025-09-12 21:05:06,169: ERROR : 980687175: [Errno 13] Permission denied: 'artifacts\\data_transformation']
Traceback (most recent call last):
  File "C:\Users\bibhu\AppData\Local\Temp\ipykernel_6860\980687175.py", line 5, in <module>
    data_transformation.train_test_data_splitting()
    ~~~~~~~~~~~~~~~~~~~~~~~~~~~~~~~~~~~~~~~~~~~~~^^
  File "C:\Users\bibhu\AppData\Local\Temp\ipykernel_6860\45674994.py", line 8, in train_test_data_splitting
    train.to_csv(self.config.root_dir ,"train.csv", index=False)
    ~~~~~~~~~~~~^^^^^^^^^^^^^^^^^^^^^^^^^^^^^^^^^^^^^^^^^^^^^^^^
  File "d:\DE\ML OPs\DSusingMLOps\venv\Lib\site-packages\pandas\util\_decorators.py", line 333, in wrapper
    return func(*args, **kwargs)
  File "d:\DE\ML OPs\DSusingMLOps\venv\Lib\site-packages\pandas\core\generic.py", line 3986, in to_csv
    return DataFrameRenderer(formatter).to_csv(
           ~~~~~~~~~~~~~~~~~~~~~~~~~~~~~~~~~~~^
        path_or_buf,
        ^^^^^^^^^^^^
    ...<14 lines>...
        storage_options=storage_options,
        ^^^^^^^^^^^^^^^^^^^^^^^^^^^^^^^^
    )
    ^
  File "d:\DE\ML OPs\DSusingMLOps\venv\Lib\site-packages\pandas\io\formats\format.py", line 1014, in to_csv
    csv_formatter.save()
    ~~~~~~~~~~~~~~~~~~^^
  File "d:\DE\ML OPs\DSusingMLOps\venv\Lib\site-packages\pandas\io\formats\csvs.py", line 251, in save
    with get_handle(
         ~~~~~~~~~~^
        self.filepath_or_buffer,
        ^^^^^^^^^^^^^^^^^^^^^^^^
    ...<4 lines>...
        storage_options=self.storage_options,
        ^^^^^^^^^^^^^^^^^^^^^^^^^^^^^^^^^^^^^
    ) as handles:
    ^
  File "d:\DE\ML OPs\DSusingMLOps\venv\Lib\site-packages\pandas\io\common.py", line 873, in get_handle
    handle = open(
        handle,
    ...<3 lines>...
        newline="",
    )
PermissionError: [Errno 13] Permission denied: 'artifacts\\data_transformation'
[2025-09-12 21:05:36,023: INFO : common: yaml file: config\config.yaml loaded sucessfully]
[2025-09-12 21:05:36,026: INFO : common: yaml file: params.yaml loaded sucessfully]
[2025-09-12 21:05:36,031: INFO : common: yaml file: schema.yaml loaded sucessfully]
[2025-09-12 21:05:36,034: INFO : common: created directory at path :artifacts]
[2025-09-12 21:05:36,035: INFO : common: created directory at path :artifacts/data_transformation]
[2025-09-12 21:05:36,047: ERROR : 980687175: [Errno 13] Permission denied: 'artifacts\\data_transformation']
Traceback (most recent call last):
  File "C:\Users\bibhu\AppData\Local\Temp\ipykernel_6860\980687175.py", line 5, in <module>
    data_transformation.train_test_data_splitting()
    ~~~~~~~~~~~~~~~~~~~~~~~~~~~~~~~~~~~~~~~~~~~~~^^
  File "C:\Users\bibhu\AppData\Local\Temp\ipykernel_6860\45674994.py", line 8, in train_test_data_splitting
    train.to_csv(self.config.root_dir ,"train.csv", index=False)
    ~~~~~~~~~~~~^^^^^^^^^^^^^^^^^^^^^^^^^^^^^^^^^^^^^^^^^^^^^^^^
  File "d:\DE\ML OPs\DSusingMLOps\venv\Lib\site-packages\pandas\util\_decorators.py", line 333, in wrapper
    return func(*args, **kwargs)
  File "d:\DE\ML OPs\DSusingMLOps\venv\Lib\site-packages\pandas\core\generic.py", line 3986, in to_csv
    return DataFrameRenderer(formatter).to_csv(
           ~~~~~~~~~~~~~~~~~~~~~~~~~~~~~~~~~~~^
        path_or_buf,
        ^^^^^^^^^^^^
    ...<14 lines>...
        storage_options=storage_options,
        ^^^^^^^^^^^^^^^^^^^^^^^^^^^^^^^^
    )
    ^
  File "d:\DE\ML OPs\DSusingMLOps\venv\Lib\site-packages\pandas\io\formats\format.py", line 1014, in to_csv
    csv_formatter.save()
    ~~~~~~~~~~~~~~~~~~^^
  File "d:\DE\ML OPs\DSusingMLOps\venv\Lib\site-packages\pandas\io\formats\csvs.py", line 251, in save
    with get_handle(
         ~~~~~~~~~~^
        self.filepath_or_buffer,
        ^^^^^^^^^^^^^^^^^^^^^^^^
    ...<4 lines>...
        storage_options=self.storage_options,
        ^^^^^^^^^^^^^^^^^^^^^^^^^^^^^^^^^^^^^
    ) as handles:
    ^
  File "d:\DE\ML OPs\DSusingMLOps\venv\Lib\site-packages\pandas\io\common.py", line 873, in get_handle
    handle = open(
        handle,
    ...<3 lines>...
        newline="",
    )
PermissionError: [Errno 13] Permission denied: 'artifacts\\data_transformation'
[2025-09-12 21:06:46,087: INFO : common: yaml file: config\config.yaml loaded sucessfully]
[2025-09-12 21:06:46,089: INFO : common: yaml file: params.yaml loaded sucessfully]
[2025-09-12 21:06:46,092: INFO : common: yaml file: schema.yaml loaded sucessfully]
[2025-09-12 21:06:46,094: INFO : common: created directory at path :artifacts]
[2025-09-12 21:06:46,095: INFO : common: created directory at path :artifacts/data_transformation]
[2025-09-12 21:06:46,102: ERROR : 980687175: [Errno 13] Permission denied: 'artifacts\\data_transformation']
Traceback (most recent call last):
  File "C:\Users\bibhu\AppData\Local\Temp\ipykernel_6860\980687175.py", line 5, in <module>
    data_transformation.train_test_data_splitting()
    ~~~~~~~~~~~~~~~~~~~~~~~~~~~~~~~~~~~~~~~~~~~~~^^
  File "C:\Users\bibhu\AppData\Local\Temp\ipykernel_6860\45674994.py", line 8, in train_test_data_splitting
    train.to_csv(self.config.root_dir ,"train.csv", index=False)
    ~~~~~~~~~~~~^^^^^^^^^^^^^^^^^^^^^^^^^^^^^^^^^^^^^^^^^^^^^^^^
  File "d:\DE\ML OPs\DSusingMLOps\venv\Lib\site-packages\pandas\util\_decorators.py", line 333, in wrapper
    return func(*args, **kwargs)
  File "d:\DE\ML OPs\DSusingMLOps\venv\Lib\site-packages\pandas\core\generic.py", line 3986, in to_csv
    return DataFrameRenderer(formatter).to_csv(
           ~~~~~~~~~~~~~~~~~~~~~~~~~~~~~~~~~~~^
        path_or_buf,
        ^^^^^^^^^^^^
    ...<14 lines>...
        storage_options=storage_options,
        ^^^^^^^^^^^^^^^^^^^^^^^^^^^^^^^^
    )
    ^
  File "d:\DE\ML OPs\DSusingMLOps\venv\Lib\site-packages\pandas\io\formats\format.py", line 1014, in to_csv
    csv_formatter.save()
    ~~~~~~~~~~~~~~~~~~^^
  File "d:\DE\ML OPs\DSusingMLOps\venv\Lib\site-packages\pandas\io\formats\csvs.py", line 251, in save
    with get_handle(
         ~~~~~~~~~~^
        self.filepath_or_buffer,
        ^^^^^^^^^^^^^^^^^^^^^^^^
    ...<4 lines>...
        storage_options=self.storage_options,
        ^^^^^^^^^^^^^^^^^^^^^^^^^^^^^^^^^^^^^
    ) as handles:
    ^
  File "d:\DE\ML OPs\DSusingMLOps\venv\Lib\site-packages\pandas\io\common.py", line 873, in get_handle
    handle = open(
        handle,
    ...<3 lines>...
        newline="",
    )
PermissionError: [Errno 13] Permission denied: 'artifacts\\data_transformation'
[2025-09-12 21:08:19,767: INFO : common: yaml file: config\config.yaml loaded sucessfully]
[2025-09-12 21:08:19,771: INFO : common: yaml file: params.yaml loaded sucessfully]
[2025-09-12 21:08:19,777: INFO : common: yaml file: schema.yaml loaded sucessfully]
[2025-09-12 21:08:19,778: INFO : common: created directory at path :artifacts]
[2025-09-12 21:08:19,780: INFO : common: created directory at path :artifacts/data_transformation]
[2025-09-12 21:08:19,792: ERROR : 980687175: [Errno 13] Permission denied: 'artifacts\\data_transformation']
Traceback (most recent call last):
  File "C:\Users\bibhu\AppData\Local\Temp\ipykernel_6860\980687175.py", line 5, in <module>
    data_transformation.train_test_data_splitting()
    ~~~~~~~~~~~~~~~~~~~~~~~~~~~~~~~~~~~~~~~~~~~~~^^
  File "C:\Users\bibhu\AppData\Local\Temp\ipykernel_6860\45674994.py", line 8, in train_test_data_splitting
    train.to_csv(self.config.root_dir ,"train.csv", index=False)
    ~~~~~~~~~~~~^^^^^^^^^^^^^^^^^^^^^^^^^^^^^^^^^^^^^^^^^^^^^^^^
  File "d:\DE\ML OPs\DSusingMLOps\venv\Lib\site-packages\pandas\util\_decorators.py", line 333, in wrapper
    return func(*args, **kwargs)
  File "d:\DE\ML OPs\DSusingMLOps\venv\Lib\site-packages\pandas\core\generic.py", line 3986, in to_csv
    return DataFrameRenderer(formatter).to_csv(
           ~~~~~~~~~~~~~~~~~~~~~~~~~~~~~~~~~~~^
        path_or_buf,
        ^^^^^^^^^^^^
    ...<14 lines>...
        storage_options=storage_options,
        ^^^^^^^^^^^^^^^^^^^^^^^^^^^^^^^^
    )
    ^
  File "d:\DE\ML OPs\DSusingMLOps\venv\Lib\site-packages\pandas\io\formats\format.py", line 1014, in to_csv
    csv_formatter.save()
    ~~~~~~~~~~~~~~~~~~^^
  File "d:\DE\ML OPs\DSusingMLOps\venv\Lib\site-packages\pandas\io\formats\csvs.py", line 251, in save
    with get_handle(
         ~~~~~~~~~~^
        self.filepath_or_buffer,
        ^^^^^^^^^^^^^^^^^^^^^^^^
    ...<4 lines>...
        storage_options=self.storage_options,
        ^^^^^^^^^^^^^^^^^^^^^^^^^^^^^^^^^^^^^
    ) as handles:
    ^
  File "d:\DE\ML OPs\DSusingMLOps\venv\Lib\site-packages\pandas\io\common.py", line 873, in get_handle
    handle = open(
        handle,
    ...<3 lines>...
        newline="",
    )
PermissionError: [Errno 13] Permission denied: 'artifacts\\data_transformation'
[2025-09-12 21:09:00,179: INFO : common: yaml file: config\config.yaml loaded sucessfully]
[2025-09-12 21:09:00,181: INFO : common: yaml file: params.yaml loaded sucessfully]
[2025-09-12 21:09:00,183: INFO : common: yaml file: schema.yaml loaded sucessfully]
[2025-09-12 21:09:00,185: INFO : common: created directory at path :artifacts]
[2025-09-12 21:09:00,187: INFO : common: created directory at path :artifacts/data_transformation]
[2025-09-12 21:09:00,212: INFO : 2134617499: Train and Test data saved in artifacts\data_transformation]
[2025-09-12 21:09:00,213: INFO : 2134617499: (1279, 12)]
[2025-09-12 21:09:00,214: INFO : 2134617499: (320, 12)]
[2025-09-13 21:49:20,186: INFO : main: Welcome to custom logger DS]
[2025-09-13 21:49:20,186: INFO : main: >>>>>>>>>>>>>>> Stage Data Ingestion Stage Started  <<<<<<<<<<<<<]
[2025-09-13 21:49:20,194: INFO : common: yaml file: config\config.yaml loaded sucessfully]
[2025-09-13 21:49:20,201: INFO : common: yaml file: params.yaml loaded sucessfully]
[2025-09-13 21:49:20,210: INFO : common: yaml file: schema.yaml loaded sucessfully]
[2025-09-13 21:49:20,211: INFO : common: created directory at path :artifacts]
[2025-09-13 21:49:20,211: INFO : common: created directory at path :artifacts/data_ingestion]
[2025-09-13 21:49:20,211: INFO : data_ingestion: File already exists]
[2025-09-13 21:49:20,224: INFO : main: >>>>>> Stage Data Ingestion Stage Completed  <<<<<<<]
[2025-09-13 21:49:20,224: INFO : main: >>>>>>>>>>>>>>> Stage Data Validation  Stage Started  <<<<<<<<<<<<<]
[2025-09-13 21:49:20,225: INFO : common: yaml file: config\config.yaml loaded sucessfully]
[2025-09-13 21:49:20,226: INFO : common: yaml file: params.yaml loaded sucessfully]
[2025-09-13 21:49:20,228: INFO : common: yaml file: schema.yaml loaded sucessfully]
[2025-09-13 21:49:20,229: INFO : common: created directory at path :artifacts]
[2025-09-13 21:49:20,229: INFO : common: created directory at path :artifacts/data_validation]
[2025-09-13 21:49:20,247: INFO : main: >>>>>> Stage Data Validation  Stage Completed  <<<<<<<]
[2025-09-13 21:49:20,247: INFO : main: >>>>>>>>>>>>>>> Stage Data Transformation Stage Started  <<<<<<<<<<<<<]
[2025-09-13 21:49:20,247: ERROR : main: [Errno 2] No such file or directory: 'artifacts\\data_validation\\STATUS_FILE']
Traceback (most recent call last):
  File "D:\DE\ML OPs\DSusingMLOps\main.py", line 34, in <module>
    obj.initiate_Data_Transformation()
    ~~~~~~~~~~~~~~~~~~~~~~~~~~~~~~~~^^
  File "D:\DE\ML OPs\DSusingMLOps\src\datascience\pipeline\data_transformation_pipeline.py", line 23, in initiate_Data_Transformation
    raise e
  File "D:\DE\ML OPs\DSusingMLOps\src\datascience\pipeline\data_transformation_pipeline.py", line 13, in initiate_Data_Transformation
    with open(Path("artifacts/data_validation/STATUS_FILE"), 'r') as f:
         ~~~~^^^^^^^^^^^^^^^^^^^^^^^^^^^^^^^^^^^^^^^^^^^^^^^^^^^^
FileNotFoundError: [Errno 2] No such file or directory: 'artifacts\\data_validation\\STATUS_FILE'
[2025-09-13 21:50:18,236: INFO : main: Welcome to custom logger DS]
[2025-09-13 21:50:18,236: INFO : main: >>>>>>>>>>>>>>> Stage Data Ingestion Stage Started  <<<<<<<<<<<<<]
[2025-09-13 21:50:18,238: INFO : common: yaml file: config\config.yaml loaded sucessfully]
[2025-09-13 21:50:18,239: INFO : common: yaml file: params.yaml loaded sucessfully]
[2025-09-13 21:50:18,241: INFO : common: yaml file: schema.yaml loaded sucessfully]
[2025-09-13 21:50:18,241: INFO : common: created directory at path :artifacts]
[2025-09-13 21:50:18,242: INFO : common: created directory at path :artifacts/data_ingestion]
[2025-09-13 21:50:18,242: INFO : data_ingestion: File already exists]
[2025-09-13 21:50:18,244: INFO : main: >>>>>> Stage Data Ingestion Stage Completed  <<<<<<<]
[2025-09-13 21:50:18,244: INFO : main: >>>>>>>>>>>>>>> Stage Data Validation  Stage Started  <<<<<<<<<<<<<]
[2025-09-13 21:50:18,246: INFO : common: yaml file: config\config.yaml loaded sucessfully]
[2025-09-13 21:50:18,246: INFO : common: yaml file: params.yaml loaded sucessfully]
[2025-09-13 21:50:18,248: INFO : common: yaml file: schema.yaml loaded sucessfully]
[2025-09-13 21:50:18,249: INFO : common: created directory at path :artifacts]
[2025-09-13 21:50:18,249: INFO : common: created directory at path :artifacts/data_validation]
[2025-09-13 21:50:18,271: INFO : main: >>>>>> Stage Data Validation  Stage Completed  <<<<<<<]
[2025-09-13 21:50:18,271: INFO : main: >>>>>>>>>>>>>>> Stage Data Transformation Stage Started  <<<<<<<<<<<<<]
[2025-09-13 21:50:18,281: ERROR : main: Data Validation Failed, Please check the logs]
Traceback (most recent call last):
  File "D:\DE\ML OPs\DSusingMLOps\main.py", line 34, in <module>
    obj.initiate_Data_Transformation()
    ~~~~~~~~~~~~~~~~~~~~~~~~~~~~~~~~^^
  File "D:\DE\ML OPs\DSusingMLOps\src\datascience\pipeline\data_transformation_pipeline.py", line 23, in initiate_Data_Transformation
    raise e
  File "D:\DE\ML OPs\DSusingMLOps\src\datascience\pipeline\data_transformation_pipeline.py", line 21, in initiate_Data_Transformation
    raise Exception("Data Validation Failed, Please check the logs")
Exception: Data Validation Failed, Please check the logs
[2025-09-13 21:51:20,426: INFO : main: Welcome to custom logger DS]
[2025-09-13 21:51:20,426: INFO : main: >>>>>>>>>>>>>>> Stage Data Ingestion Stage Started  <<<<<<<<<<<<<]
[2025-09-13 21:51:20,428: INFO : common: yaml file: config\config.yaml loaded sucessfully]
[2025-09-13 21:51:20,428: INFO : common: yaml file: params.yaml loaded sucessfully]
[2025-09-13 21:51:20,430: INFO : common: yaml file: schema.yaml loaded sucessfully]
[2025-09-13 21:51:20,430: INFO : common: created directory at path :artifacts]
[2025-09-13 21:51:20,431: INFO : common: created directory at path :artifacts/data_ingestion]
[2025-09-13 21:51:20,431: INFO : data_ingestion: File already exists]
[2025-09-13 21:51:20,432: INFO : main: >>>>>> Stage Data Ingestion Stage Completed  <<<<<<<]
[2025-09-13 21:51:20,432: INFO : main: >>>>>>>>>>>>>>> Stage Data Validation  Stage Started  <<<<<<<<<<<<<]
[2025-09-13 21:51:20,434: INFO : common: yaml file: config\config.yaml loaded sucessfully]
[2025-09-13 21:51:20,434: INFO : common: yaml file: params.yaml loaded sucessfully]
[2025-09-13 21:51:20,436: INFO : common: yaml file: schema.yaml loaded sucessfully]
[2025-09-13 21:51:20,436: INFO : common: created directory at path :artifacts]
[2025-09-13 21:51:20,437: INFO : common: created directory at path :artifacts/data_validation]
[2025-09-13 21:51:20,455: INFO : main: >>>>>> Stage Data Validation  Stage Completed  <<<<<<<]
[2025-09-13 21:51:20,455: INFO : main: >>>>>>>>>>>>>>> Stage Data Transformation Stage Started  <<<<<<<<<<<<<]
[2025-09-13 21:51:20,457: ERROR : main: Data Validation Failed, Please check the logs]
Traceback (most recent call last):
  File "D:\DE\ML OPs\DSusingMLOps\main.py", line 34, in <module>
    obj.initiate_Data_Transformation()
    ~~~~~~~~~~~~~~~~~~~~~~~~~~~~~~~~^^
  File "D:\DE\ML OPs\DSusingMLOps\src\datascience\pipeline\data_transformation_pipeline.py", line 23, in initiate_Data_Transformation
    raise e
  File "D:\DE\ML OPs\DSusingMLOps\src\datascience\pipeline\data_transformation_pipeline.py", line 21, in initiate_Data_Transformation
    raise Exception("Data Validation Failed, Please check the logs")
Exception: Data Validation Failed, Please check the logs
[2025-09-13 21:52:18,878: INFO : main: Welcome to custom logger DS]
[2025-09-13 21:52:18,878: INFO : main: >>>>>>>>>>>>>>> Stage Data Ingestion Stage Started  <<<<<<<<<<<<<]
[2025-09-13 21:52:18,880: INFO : common: yaml file: config\config.yaml loaded sucessfully]
[2025-09-13 21:52:18,881: INFO : common: yaml file: params.yaml loaded sucessfully]
[2025-09-13 21:52:18,882: INFO : common: yaml file: schema.yaml loaded sucessfully]
[2025-09-13 21:52:18,883: INFO : common: created directory at path :artifacts]
[2025-09-13 21:52:18,883: INFO : common: created directory at path :artifacts/data_ingestion]
[2025-09-13 21:52:18,883: INFO : data_ingestion: File already exists]
[2025-09-13 21:52:18,885: INFO : main: >>>>>> Stage Data Ingestion Stage Completed  <<<<<<<]
[2025-09-13 21:52:18,885: INFO : main: >>>>>>>>>>>>>>> Stage Data Validation  Stage Started  <<<<<<<<<<<<<]
[2025-09-13 21:52:18,887: INFO : common: yaml file: config\config.yaml loaded sucessfully]
[2025-09-13 21:52:18,887: INFO : common: yaml file: params.yaml loaded sucessfully]
[2025-09-13 21:52:18,889: INFO : common: yaml file: schema.yaml loaded sucessfully]
[2025-09-13 21:52:18,889: INFO : common: created directory at path :artifacts]
[2025-09-13 21:52:18,890: INFO : common: created directory at path :artifacts/data_validation]
[2025-09-13 21:52:18,909: INFO : main: >>>>>> Stage Data Validation  Stage Completed  <<<<<<<]
[2025-09-13 21:52:18,909: INFO : main: >>>>>>>>>>>>>>> Stage Data Transformation Stage Started  <<<<<<<<<<<<<]
[2025-09-13 21:52:18,911: ERROR : main: Data Validation Failed, Please check the logs]
Traceback (most recent call last):
  File "D:\DE\ML OPs\DSusingMLOps\main.py", line 34, in <module>
    obj.initiate_Data_Transformation()
    ~~~~~~~~~~~~~~~~~~~~~~~~~~~~~~~~^^
  File "D:\DE\ML OPs\DSusingMLOps\src\datascience\pipeline\data_transformation_pipeline.py", line 23, in initiate_Data_Transformation
    raise e
  File "D:\DE\ML OPs\DSusingMLOps\src\datascience\pipeline\data_transformation_pipeline.py", line 21, in initiate_Data_Transformation
    raise Exception("Data Validation Failed, Please check the logs")
Exception: Data Validation Failed, Please check the logs
[2025-09-13 21:53:32,673: INFO : main: Welcome to custom logger DS]
[2025-09-13 21:53:32,674: INFO : main: >>>>>>>>>>>>>>> Stage Data Ingestion Stage Started  <<<<<<<<<<<<<]
[2025-09-13 21:53:32,675: INFO : common: yaml file: config\config.yaml loaded sucessfully]
[2025-09-13 21:53:32,676: INFO : common: yaml file: params.yaml loaded sucessfully]
[2025-09-13 21:53:32,678: INFO : common: yaml file: schema.yaml loaded sucessfully]
[2025-09-13 21:53:32,678: INFO : common: created directory at path :artifacts]
[2025-09-13 21:53:32,679: INFO : common: created directory at path :artifacts/data_ingestion]
[2025-09-13 21:53:33,364: INFO : data_ingestion: artifacts/data_ingestion/data.zip download! with following info: 
Connection: close
Content-Length: 23329
Cache-Control: max-age=300
Content-Security-Policy: default-src 'none'; style-src 'unsafe-inline'; sandbox
Content-Type: application/zip
ETag: "c69888a4ae59bc5a893392785a938ccd4937981c06ba8a9d6a21aa52b4ab5b6e"
Strict-Transport-Security: max-age=31536000
X-Content-Type-Options: nosniff
X-Frame-Options: deny
X-XSS-Protection: 1; mode=block
X-GitHub-Request-Id: E118:159395:A9ECDF:DB7826:68C6201C
Accept-Ranges: bytes
Date: Sun, 14 Sep 2025 01:53:32 GMT
Via: 1.1 varnish
X-Served-By: cache-yyz4525-YYZ
X-Cache: MISS
X-Cache-Hits: 0
X-Timer: S1757814813.582108,VS0,VE55
Vary: Authorization,Accept-Encoding
Access-Control-Allow-Origin: *
Cross-Origin-Resource-Policy: cross-origin
X-Fastly-Request-ID: 1f3401f29ec0fadd76198b7e9b39e46fb0b6ec16
Expires: Sun, 14 Sep 2025 01:58:32 GMT
Source-Age: 0

]
[2025-09-13 21:53:33,376: INFO : main: >>>>>> Stage Data Ingestion Stage Completed  <<<<<<<]
[2025-09-13 21:53:33,376: INFO : main: >>>>>>>>>>>>>>> Stage Data Validation  Stage Started  <<<<<<<<<<<<<]
[2025-09-13 21:53:33,378: INFO : common: yaml file: config\config.yaml loaded sucessfully]
[2025-09-13 21:53:33,379: INFO : common: yaml file: params.yaml loaded sucessfully]
[2025-09-13 21:53:33,381: INFO : common: yaml file: schema.yaml loaded sucessfully]
[2025-09-13 21:53:33,382: INFO : common: created directory at path :artifacts]
[2025-09-13 21:53:33,382: INFO : common: created directory at path :artifacts/data_validation]
[2025-09-13 21:53:33,399: INFO : main: >>>>>> Stage Data Validation  Stage Completed  <<<<<<<]
[2025-09-13 21:53:33,400: INFO : main: >>>>>>>>>>>>>>> Stage Data Transformation Stage Started  <<<<<<<<<<<<<]
[2025-09-13 21:53:33,401: ERROR : main: Data Validation Failed, Please check the logs]
Traceback (most recent call last):
  File "D:\DE\ML OPs\DSusingMLOps\main.py", line 34, in <module>
    obj.initiate_Data_Transformation()
    ~~~~~~~~~~~~~~~~~~~~~~~~~~~~~~~~^^
  File "D:\DE\ML OPs\DSusingMLOps\src\datascience\pipeline\data_transformation_pipeline.py", line 23, in initiate_Data_Transformation
    raise e
  File "D:\DE\ML OPs\DSusingMLOps\src\datascience\pipeline\data_transformation_pipeline.py", line 21, in initiate_Data_Transformation
    raise Exception("Data Validation Failed, Please check the logs")
Exception: Data Validation Failed, Please check the logs
[2025-09-13 21:55:17,205: INFO : main: Welcome to custom logger DS]
[2025-09-13 21:55:17,206: INFO : main: >>>>>>>>>>>>>>> Stage Data Ingestion Stage Started  <<<<<<<<<<<<<]
[2025-09-13 21:55:17,207: INFO : common: yaml file: config\config.yaml loaded sucessfully]
[2025-09-13 21:55:17,208: INFO : common: yaml file: params.yaml loaded sucessfully]
[2025-09-13 21:55:17,209: INFO : common: yaml file: schema.yaml loaded sucessfully]
[2025-09-13 21:55:17,210: INFO : common: created directory at path :artifacts]
[2025-09-13 21:55:17,210: INFO : common: created directory at path :artifacts/data_ingestion]
[2025-09-13 21:55:17,211: INFO : data_ingestion: File already exists]
[2025-09-13 21:55:17,212: INFO : main: >>>>>> Stage Data Ingestion Stage Completed  <<<<<<<]
[2025-09-13 21:55:17,212: INFO : main: >>>>>>>>>>>>>>> Stage Data Validation  Stage Started  <<<<<<<<<<<<<]
[2025-09-13 21:55:17,214: INFO : common: yaml file: config\config.yaml loaded sucessfully]
[2025-09-13 21:55:17,215: INFO : common: yaml file: params.yaml loaded sucessfully]
[2025-09-13 21:55:17,216: INFO : common: yaml file: schema.yaml loaded sucessfully]
[2025-09-13 21:55:17,217: INFO : common: created directory at path :artifacts]
[2025-09-13 21:55:17,217: INFO : common: created directory at path :artifacts/data_validation]
[2025-09-13 21:55:17,235: INFO : main: >>>>>> Stage Data Validation  Stage Completed  <<<<<<<]
[2025-09-13 21:55:17,235: INFO : main: >>>>>>>>>>>>>>> Stage Data Transformation Stage Started  <<<<<<<<<<<<<]
[2025-09-13 21:55:17,236: ERROR : main: Data Validation Failed, Please check the logs]
Traceback (most recent call last):
  File "D:\DE\ML OPs\DSusingMLOps\main.py", line 34, in <module>
    obj.initiate_Data_Transformation()
    ~~~~~~~~~~~~~~~~~~~~~~~~~~~~~~~~^^
  File "D:\DE\ML OPs\DSusingMLOps\src\datascience\pipeline\data_transformation_pipeline.py", line 23, in initiate_Data_Transformation
    raise e
  File "D:\DE\ML OPs\DSusingMLOps\src\datascience\pipeline\data_transformation_pipeline.py", line 21, in initiate_Data_Transformation
    raise Exception("Data Validation Failed, Please check the logs")
Exception: Data Validation Failed, Please check the logs
[2025-09-13 22:01:15,253: INFO : common: yaml file: config\config.yaml loaded sucessfully]
[2025-09-13 22:01:15,254: INFO : common: yaml file: params.yaml loaded sucessfully]
[2025-09-13 22:01:15,257: INFO : common: yaml file: schema.yaml loaded sucessfully]
[2025-09-13 22:01:15,259: INFO : common: created directory at path :artifacts]
[2025-09-13 22:01:15,260: INFO : common: created directory at path :artifacts/data_transformation]
[2025-09-13 22:01:52,355: INFO : main: Welcome to custom logger DS]
[2025-09-13 22:01:52,355: INFO : main: >>>>>>>>>>>>>>> Stage Data Ingestion Stage Started  <<<<<<<<<<<<<]
[2025-09-13 22:01:52,357: INFO : common: yaml file: config\config.yaml loaded sucessfully]
[2025-09-13 22:01:52,357: INFO : common: yaml file: params.yaml loaded sucessfully]
[2025-09-13 22:01:52,359: INFO : common: yaml file: schema.yaml loaded sucessfully]
[2025-09-13 22:01:52,359: INFO : common: created directory at path :artifacts]
[2025-09-13 22:01:52,359: INFO : common: created directory at path :artifacts/data_ingestion]
[2025-09-13 22:01:52,360: INFO : data_ingestion: File already exists]
[2025-09-13 22:01:52,361: INFO : main: >>>>>> Stage Data Ingestion Stage Completed  <<<<<<<]
[2025-09-13 22:01:52,361: INFO : main: >>>>>>>>>>>>>>> Stage Data Validation  Stage Started  <<<<<<<<<<<<<]
[2025-09-13 22:01:52,363: INFO : common: yaml file: config\config.yaml loaded sucessfully]
[2025-09-13 22:01:52,363: INFO : common: yaml file: params.yaml loaded sucessfully]
[2025-09-13 22:01:52,366: INFO : common: yaml file: schema.yaml loaded sucessfully]
[2025-09-13 22:01:52,366: INFO : common: created directory at path :artifacts]
[2025-09-13 22:01:52,366: INFO : common: created directory at path :artifacts/data_validation]
[2025-09-13 22:01:52,384: INFO : main: >>>>>> Stage Data Validation  Stage Completed  <<<<<<<]
[2025-09-13 22:01:52,384: INFO : main: >>>>>>>>>>>>>>> Stage Data Transformation Stage Started  <<<<<<<<<<<<<]
[2025-09-13 22:01:52,387: INFO : common: yaml file: config\config.yaml loaded sucessfully]
[2025-09-13 22:01:52,388: INFO : common: yaml file: params.yaml loaded sucessfully]
[2025-09-13 22:01:52,390: INFO : common: yaml file: schema.yaml loaded sucessfully]
[2025-09-13 22:01:52,391: INFO : common: created directory at path :artifacts]
[2025-09-13 22:01:52,391: INFO : common: created directory at path :artifacts/data_transformation]
[2025-09-13 22:01:52,418: INFO : data_transformation: Train and Test data saved in artifacts\data_transformation]
[2025-09-13 22:01:52,418: INFO : data_transformation: (1279, 12)]
[2025-09-13 22:01:52,419: INFO : data_transformation: (320, 12)]
[2025-09-13 22:01:52,419: INFO : main: >>>>>> Stage Data Transformation Stage Completed  <<<<<<<]
[2025-09-13 22:39:18,439: INFO : common: yaml file: config\config.yaml loaded sucessfully]
[2025-09-13 22:39:18,441: INFO : common: yaml file: params.yaml loaded sucessfully]
[2025-09-13 22:39:18,443: INFO : common: yaml file: schema.yaml loaded sucessfully]
[2025-09-13 22:39:18,445: INFO : common: created directory at path :artifacts]
[2025-09-13 22:39:18,446: ERROR : 1556057569: "'ConfigBox' object has no attribute 'target_column'"]
Traceback (most recent call last):
  File "box\\box.py", line 594, in box.box.Box.__getitem__
KeyError: 'target_column'

The above exception was the direct cause of the following exception:

Traceback (most recent call last):
  File "box\\box.py", line 633, in box.box.Box.__getattr__
  File "box\\box.py", line 621, in box.box.Box.__getitem__
box.exceptions.BoxKeyError: "'target_column'"

During handling of the above exception, another exception occurred:

Traceback (most recent call last):
  File "box\\box.py", line 635, in box.box.Box.__getattr__
AttributeError: 'ConfigBox' object has no attribute 'target_column'

The above exception was the direct cause of the following exception:

Traceback (most recent call last):
  File "box\\config_box.py", line 29, in box.config_box.ConfigBox.__getattr__
  File "box\\box.py", line 649, in box.box.Box.__getattr__
box.exceptions.BoxKeyError: "'ConfigBox' object has no attribute 'target_column'"

During handling of the above exception, another exception occurred:

Traceback (most recent call last):
  File "box\\box.py", line 594, in box.box.Box.__getitem__
KeyError: 'target_column'

The above exception was the direct cause of the following exception:

Traceback (most recent call last):
  File "box\\box.py", line 633, in box.box.Box.__getattr__
  File "box\\box.py", line 621, in box.box.Box.__getitem__
box.exceptions.BoxKeyError: "'target_column'"

During handling of the above exception, another exception occurred:

Traceback (most recent call last):
  File "box\\box.py", line 635, in box.box.Box.__getattr__
AttributeError: 'ConfigBox' object has no attribute 'target_column'

The above exception was the direct cause of the following exception:

Traceback (most recent call last):
  File "C:\Users\bibhu\AppData\Local\Temp\ipykernel_18704\1556057569.py", line 3, in <module>
    model_trainer_config = config.get_model_trainer_config()
  File "C:\Users\bibhu\AppData\Local\Temp\ipykernel_18704\959036332.py", line 20, in get_model_trainer_config
    target_column=self.schema.target_column
                  ^^^^^^^^^^^^^^^^^^^^^^^^^
  File "box\\config_box.py", line 31, in box.config_box.ConfigBox.__getattr__
  File "box\\box.py", line 649, in box.box.Box.__getattr__
box.exceptions.BoxKeyError: "'ConfigBox' object has no attribute 'target_column'"
[2025-09-13 22:40:28,779: INFO : common: yaml file: config\config.yaml loaded sucessfully]
[2025-09-13 22:40:28,781: INFO : common: yaml file: params.yaml loaded sucessfully]
[2025-09-13 22:40:28,782: INFO : common: yaml file: schema.yaml loaded sucessfully]
[2025-09-13 22:40:28,784: INFO : common: created directory at path :artifacts]
[2025-09-13 22:40:28,785: ERROR : 1556057569: "'ConfigBox' object has no attribute 'name'"]
Traceback (most recent call last):
  File "box\\box.py", line 594, in box.box.Box.__getitem__
KeyError: 'name'

The above exception was the direct cause of the following exception:

Traceback (most recent call last):
  File "box\\box.py", line 633, in box.box.Box.__getattr__
  File "box\\box.py", line 621, in box.box.Box.__getitem__
box.exceptions.BoxKeyError: "'name'"

During handling of the above exception, another exception occurred:

Traceback (most recent call last):
  File "box\\box.py", line 635, in box.box.Box.__getattr__
AttributeError: 'ConfigBox' object has no attribute 'name'

The above exception was the direct cause of the following exception:

Traceback (most recent call last):
  File "box\\config_box.py", line 29, in box.config_box.ConfigBox.__getattr__
  File "box\\box.py", line 649, in box.box.Box.__getattr__
box.exceptions.BoxKeyError: "'ConfigBox' object has no attribute 'name'"

During handling of the above exception, another exception occurred:

Traceback (most recent call last):
  File "box\\box.py", line 594, in box.box.Box.__getitem__
KeyError: 'name'

The above exception was the direct cause of the following exception:

Traceback (most recent call last):
  File "box\\box.py", line 633, in box.box.Box.__getattr__
  File "box\\box.py", line 621, in box.box.Box.__getitem__
box.exceptions.BoxKeyError: "'name'"

During handling of the above exception, another exception occurred:

Traceback (most recent call last):
  File "box\\box.py", line 635, in box.box.Box.__getattr__
AttributeError: 'ConfigBox' object has no attribute 'name'

The above exception was the direct cause of the following exception:

Traceback (most recent call last):
  File "C:\Users\bibhu\AppData\Local\Temp\ipykernel_18704\1556057569.py", line 3, in <module>
    model_trainer_config = config.get_model_trainer_config()
  File "C:\Users\bibhu\AppData\Local\Temp\ipykernel_18704\1500275497.py", line 21, in get_model_trainer_config
    target_column=self.schema.name
                  ^^^^^^^^^^^^^^^^
  File "box\\config_box.py", line 31, in box.config_box.ConfigBox.__getattr__
  File "box\\box.py", line 649, in box.box.Box.__getattr__
box.exceptions.BoxKeyError: "'ConfigBox' object has no attribute 'name'"
[2025-09-13 22:42:58,389: INFO : common: yaml file: config\config.yaml loaded sucessfully]
[2025-09-13 22:42:58,391: INFO : common: yaml file: params.yaml loaded sucessfully]
[2025-09-13 22:42:58,393: INFO : common: yaml file: schema.yaml loaded sucessfully]
[2025-09-13 22:42:58,394: INFO : common: created directory at path :artifacts]
[2025-09-13 22:42:58,395: INFO : 1523863267: Loading training and test data]
[2025-09-13 22:42:58,419: INFO : 1523863267: Splitting features and target]
[2025-09-13 22:42:58,427: ERROR : 1556057569: "['quantity'] not found in axis"]
Traceback (most recent call last):
  File "C:\Users\bibhu\AppData\Local\Temp\ipykernel_18704\1556057569.py", line 5, in <module>
    model_trainer_instance.train_model()
    ~~~~~~~~~~~~~~~~~~~~~~~~~~~~~~~~~~^^
  File "C:\Users\bibhu\AppData\Local\Temp\ipykernel_18704\1523863267.py", line 11, in train_model
    X_train = train_data.drop(columns=[self.config.target_column], axis=1)
  File "d:\DE\ML OPs\DSusingMLOps\venv\Lib\site-packages\pandas\core\frame.py", line 5588, in drop
    return super().drop(
           ~~~~~~~~~~~~^
        labels=labels,
        ^^^^^^^^^^^^^^
    ...<5 lines>...
        errors=errors,
        ^^^^^^^^^^^^^^
    )
    ^
  File "d:\DE\ML OPs\DSusingMLOps\venv\Lib\site-packages\pandas\core\generic.py", line 4807, in drop
    obj = obj._drop_axis(labels, axis, level=level, errors=errors)
  File "d:\DE\ML OPs\DSusingMLOps\venv\Lib\site-packages\pandas\core\generic.py", line 4849, in _drop_axis
    new_axis = axis.drop(labels, errors=errors)
  File "d:\DE\ML OPs\DSusingMLOps\venv\Lib\site-packages\pandas\core\indexes\base.py", line 7136, in drop
    raise KeyError(f"{labels[mask].tolist()} not found in axis")
KeyError: "['quantity'] not found in axis"
[2025-09-13 22:44:11,235: INFO : common: yaml file: config\config.yaml loaded sucessfully]
[2025-09-13 22:44:11,237: INFO : common: yaml file: params.yaml loaded sucessfully]
[2025-09-13 22:44:11,240: INFO : common: yaml file: schema.yaml loaded sucessfully]
[2025-09-13 22:44:11,242: INFO : common: created directory at path :artifacts]
[2025-09-13 22:44:11,243: INFO : 1523863267: Loading training and test data]
[2025-09-13 22:44:11,250: INFO : 1523863267: Splitting features and target]
[2025-09-13 22:44:11,254: INFO : 1523863267: Training the model]
[2025-09-13 22:44:11,258: INFO : 1523863267: Saving the model]
[2025-09-13 22:44:11,260: INFO : 1523863267: Model saved at artifacts\model_trainer\model.joblib]
[2025-09-13 22:44:11,261: INFO : 1556057569: Model training completed successfully.]
[2025-09-13 23:14:15,514: INFO : main: Welcome to custom logger DS]
[2025-09-13 23:14:15,514: INFO : main: >>>>>>>>>>>>>>> Stage Data Ingestion Stage Started  <<<<<<<<<<<<<]
[2025-09-13 23:14:15,516: INFO : common: yaml file: config\config.yaml loaded sucessfully]
[2025-09-13 23:14:15,517: INFO : common: yaml file: params.yaml loaded sucessfully]
[2025-09-13 23:14:15,519: INFO : common: yaml file: schema.yaml loaded sucessfully]
[2025-09-13 23:14:15,519: INFO : common: created directory at path :artifacts]
[2025-09-13 23:14:15,520: INFO : common: created directory at path :artifacts/data_ingestion]
[2025-09-13 23:14:15,520: INFO : data_ingestion: File already exists]
[2025-09-13 23:14:15,521: INFO : main: >>>>>> Stage Data Ingestion Stage Completed  <<<<<<<]
[2025-09-13 23:14:15,521: INFO : main: >>>>>>>>>>>>>>> Stage Data Validation  Stage Started  <<<<<<<<<<<<<]
[2025-09-13 23:14:15,523: INFO : common: yaml file: config\config.yaml loaded sucessfully]
[2025-09-13 23:14:15,524: INFO : common: yaml file: params.yaml loaded sucessfully]
[2025-09-13 23:14:15,526: INFO : common: yaml file: schema.yaml loaded sucessfully]
[2025-09-13 23:14:15,526: INFO : common: created directory at path :artifacts]
[2025-09-13 23:14:15,526: INFO : common: created directory at path :artifacts/data_validation]
[2025-09-13 23:14:15,545: INFO : main: >>>>>> Stage Data Validation  Stage Completed  <<<<<<<]
[2025-09-13 23:14:15,545: INFO : main: >>>>>>>>>>>>>>> Stage Data Transformation Stage Started  <<<<<<<<<<<<<]
[2025-09-13 23:14:15,548: INFO : common: yaml file: config\config.yaml loaded sucessfully]
[2025-09-13 23:14:15,549: INFO : common: yaml file: params.yaml loaded sucessfully]
[2025-09-13 23:14:15,551: INFO : common: yaml file: schema.yaml loaded sucessfully]
[2025-09-13 23:14:15,551: INFO : common: created directory at path :artifacts]
[2025-09-13 23:14:15,552: INFO : common: created directory at path :artifacts/data_transformation]
[2025-09-13 23:14:15,574: INFO : data_transformation: Train and Test data saved in artifacts\data_transformation]
[2025-09-13 23:14:15,575: INFO : data_transformation: (1279, 12)]
[2025-09-13 23:14:15,575: INFO : data_transformation: (320, 12)]
[2025-09-13 23:14:15,575: INFO : main: >>>>>> Stage Data Transformation Stage Completed  <<<<<<<]
[2025-09-13 23:14:15,576: INFO : main: >>>>>>>>>>>>>>> Stage Model Training Stage Started  <<<<<<<<<<<<<]
[2025-09-13 23:14:15,578: INFO : common: yaml file: config\config.yaml loaded sucessfully]
[2025-09-13 23:14:15,579: INFO : common: yaml file: params.yaml loaded sucessfully]
[2025-09-13 23:14:15,581: INFO : common: yaml file: schema.yaml loaded sucessfully]
[2025-09-13 23:14:15,582: INFO : common: created directory at path :artifacts]
[2025-09-13 23:14:15,582: INFO : model_train: Loading training and test data]
[2025-09-13 23:14:15,608: INFO : model_train: Splitting features and target]
[2025-09-13 23:14:15,610: INFO : model_train: Training the model]
[2025-09-13 23:14:15,612: INFO : model_train: Saving the model]
[2025-09-13 23:14:15,614: INFO : model_train: Model saved at artifacts\model_trainer\model.joblib]
[2025-09-13 23:14:15,614: INFO : model_train: Model training completed successfully]
[2025-09-13 23:14:15,615: INFO : main: >>>>>> Stage Model Training Stage Completed  <<<<<<<]
[2025-09-13 23:50:15,070: INFO : common: yaml file: config\config.yaml loaded sucessfully]
[2025-09-13 23:50:15,073: INFO : common: yaml file: params.yaml loaded sucessfully]
[2025-09-13 23:50:15,076: INFO : common: yaml file: schema.yaml loaded sucessfully]
[2025-09-13 23:50:15,078: INFO : common: created directory at path :artifacts]
[2025-09-13 23:50:15,078: ERROR : 1899718429: "'ConfigBox' object has no attribute 'target_column'"]
Traceback (most recent call last):
  File "box\\box.py", line 594, in box.box.Box.__getitem__
KeyError: 'target_column'

The above exception was the direct cause of the following exception:

Traceback (most recent call last):
  File "box\\box.py", line 633, in box.box.Box.__getattr__
  File "box\\box.py", line 621, in box.box.Box.__getitem__
box.exceptions.BoxKeyError: "'target_column'"

During handling of the above exception, another exception occurred:

Traceback (most recent call last):
  File "box\\box.py", line 635, in box.box.Box.__getattr__
AttributeError: 'ConfigBox' object has no attribute 'target_column'

The above exception was the direct cause of the following exception:

Traceback (most recent call last):
  File "box\\config_box.py", line 29, in box.config_box.ConfigBox.__getattr__
  File "box\\box.py", line 649, in box.box.Box.__getattr__
box.exceptions.BoxKeyError: "'ConfigBox' object has no attribute 'target_column'"

During handling of the above exception, another exception occurred:

Traceback (most recent call last):
  File "box\\box.py", line 594, in box.box.Box.__getitem__
KeyError: 'target_column'

The above exception was the direct cause of the following exception:

Traceback (most recent call last):
  File "box\\box.py", line 633, in box.box.Box.__getattr__
  File "box\\box.py", line 621, in box.box.Box.__getitem__
box.exceptions.BoxKeyError: "'target_column'"

During handling of the above exception, another exception occurred:

Traceback (most recent call last):
  File "box\\box.py", line 635, in box.box.Box.__getattr__
AttributeError: 'ConfigBox' object has no attribute 'target_column'

The above exception was the direct cause of the following exception:

Traceback (most recent call last):
  File "C:\Users\bibhu\AppData\Local\Temp\ipykernel_22264\1899718429.py", line 3, in <module>
    model_eval_config = config.get_model_evaluation_config()
  File "C:\Users\bibhu\AppData\Local\Temp\ipykernel_22264\1314053891.py", line 12, in get_model_evaluation_config
    schema = self.schema.target_column
             ^^^^^^^^^^^^^^^^^^^^^^^^^
  File "box\\config_box.py", line 31, in box.config_box.ConfigBox.__getattr__
  File "box\\box.py", line 649, in box.box.Box.__getattr__
box.exceptions.BoxKeyError: "'ConfigBox' object has no attribute 'target_column'"
[2025-09-13 23:51:15,091: INFO : common: yaml file: config\config.yaml loaded sucessfully]
[2025-09-13 23:51:15,092: INFO : common: yaml file: params.yaml loaded sucessfully]
[2025-09-13 23:51:15,094: INFO : common: yaml file: schema.yaml loaded sucessfully]
[2025-09-13 23:51:15,096: INFO : common: created directory at path :artifacts]
[2025-09-13 23:51:15,097: INFO : common: created directory at path :artifacts/model_evaluation]
[2025-09-13 23:51:15,104: INFO : 1899718429: Model Evaluation Config: ModelEvaluationConfig(root_dir=WindowsPath('artifacts/model_evaluation'), test_data_path=WindowsPath('artifacts/data_transformation/test.csv'), model_path=WindowsPath('artifacts/model_trainer/model.joblib'), all_params=ConfigBox({'alpha': 0.2, 'l1_ratio': 0.1}), metric_file_name=WindowsPath('artifacts/model_evaluation/metrics.json'), target_column='quality', mlflow_uri='https://dagshub.com/bibhumlai/DSprojectusingMLOps.mlflow')]
[2025-09-13 23:51:15,108: INFO : 3014442867: Test data shape: (320, 12)]
[2025-09-13 23:51:15,182: INFO : 3014442867: Model: ElasticNet(alpha=0.2, l1_ratio=0.1, random_state=42)]
[2025-09-13 23:51:15,501: ERROR : 1899718429: name 'mse' is not defined]
Traceback (most recent call last):
  File "C:\Users\bibhu\AppData\Local\Temp\ipykernel_22264\1899718429.py", line 6, in <module>
    model_eval.log_into_mlflow()
    ~~~~~~~~~~~~~~~~~~~~~~~~~~^^
  File "C:\Users\bibhu\AppData\Local\Temp\ipykernel_22264\3014442867.py", line 26, in log_into_mlflow
    (rmse, mae, r2_square) = self.eval_metrics(test_y, predicted_qualities)
                             ~~~~~~~~~~~~~~~~~^^^^^^^^^^^^^^^^^^^^^^^^^^^^^
  File "C:\Users\bibhu\AppData\Local\Temp\ipykernel_22264\3014442867.py", line 9, in eval_metrics
    return  rmse, mse, r2_square
                  ^^^
NameError: name 'mse' is not defined. Did you mean: 'rmse'?
[2025-09-13 23:51:57,805: INFO : common: yaml file: config\config.yaml loaded sucessfully]
[2025-09-13 23:51:57,807: INFO : common: yaml file: params.yaml loaded sucessfully]
[2025-09-13 23:51:57,809: INFO : common: yaml file: schema.yaml loaded sucessfully]
[2025-09-13 23:51:57,810: INFO : common: created directory at path :artifacts]
[2025-09-13 23:51:57,811: INFO : common: created directory at path :artifacts/model_evaluation]
[2025-09-13 23:51:57,812: INFO : 1899718429: Model Evaluation Config: ModelEvaluationConfig(root_dir=WindowsPath('artifacts/model_evaluation'), test_data_path=WindowsPath('artifacts/data_transformation/test.csv'), model_path=WindowsPath('artifacts/model_trainer/model.joblib'), all_params=ConfigBox({'alpha': 0.2, 'l1_ratio': 0.1}), metric_file_name=WindowsPath('artifacts/model_evaluation/metrics.json'), target_column='quality', mlflow_uri='https://dagshub.com/bibhumlai/DSprojectusingMLOps.mlflow')]
[2025-09-13 23:51:57,815: INFO : 1304064896: Test data shape: (320, 12)]
[2025-09-13 23:51:57,816: INFO : 1304064896: Model: ElasticNet(alpha=0.2, l1_ratio=0.1, random_state=42)]
[2025-09-13 23:51:57,877: INFO : 1304064896: Elasticnet model (alpha=0.2, l1_ratio=0.1)]
[2025-09-13 23:51:57,878: INFO : 1304064896:   RMSE: 0.6929185588573523]
[2025-09-13 23:51:57,879: INFO : 1304064896:   MAE: 0.5543829927884041]
[2025-09-13 23:51:57,880: INFO : 1304064896:   R2: 0.2652917761622786]
[2025-09-13 23:51:57,884: ERROR : 1899718429: name 'save_json' is not defined]
Traceback (most recent call last):
  File "C:\Users\bibhu\AppData\Local\Temp\ipykernel_22264\1899718429.py", line 6, in <module>
    model_eval.log_into_mlflow()
    ~~~~~~~~~~~~~~~~~~~~~~~~~~^^
  File "C:\Users\bibhu\AppData\Local\Temp\ipykernel_22264\1304064896.py", line 34, in log_into_mlflow
    save_json(path=Path(self.config.metric_file_name), data= scores)
    ^^^^^^^^^
NameError: name 'save_json' is not defined
[2025-09-13 23:52:28,458: INFO : common: yaml file: config\config.yaml loaded sucessfully]
[2025-09-13 23:52:28,459: INFO : common: yaml file: params.yaml loaded sucessfully]
[2025-09-13 23:52:28,461: INFO : common: yaml file: schema.yaml loaded sucessfully]
[2025-09-13 23:52:28,463: INFO : common: created directory at path :artifacts]
[2025-09-13 23:52:28,465: INFO : common: created directory at path :artifacts/model_evaluation]
[2025-09-13 23:52:28,466: INFO : 1899718429: Model Evaluation Config: ModelEvaluationConfig(root_dir=WindowsPath('artifacts/model_evaluation'), test_data_path=WindowsPath('artifacts/data_transformation/test.csv'), model_path=WindowsPath('artifacts/model_trainer/model.joblib'), all_params=ConfigBox({'alpha': 0.2, 'l1_ratio': 0.1}), metric_file_name=WindowsPath('artifacts/model_evaluation/metrics.json'), target_column='quality', mlflow_uri='https://dagshub.com/bibhumlai/DSprojectusingMLOps.mlflow')]
[2025-09-13 23:52:28,468: INFO : 1304064896: Test data shape: (320, 12)]
[2025-09-13 23:52:28,470: INFO : 1304064896: Model: ElasticNet(alpha=0.2, l1_ratio=0.1, random_state=42)]
[2025-09-13 23:52:28,528: INFO : 1304064896: Elasticnet model (alpha=0.2, l1_ratio=0.1)]
[2025-09-13 23:52:28,529: INFO : 1304064896:   RMSE: 0.6929185588573523]
[2025-09-13 23:52:28,529: INFO : 1304064896:   MAE: 0.5543829927884041]
[2025-09-13 23:52:28,530: INFO : 1304064896:   R2: 0.2652917761622786]
[2025-09-13 23:52:28,531: INFO : common: json file saved at : artifacts\model_evaluation\metrics.json]
[2025-09-13 23:56:07,435: INFO : common: yaml file: config\config.yaml loaded sucessfully]
[2025-09-13 23:56:07,437: INFO : common: yaml file: params.yaml loaded sucessfully]
[2025-09-13 23:56:07,439: INFO : common: yaml file: schema.yaml loaded sucessfully]
[2025-09-13 23:56:07,441: INFO : common: created directory at path :artifacts]
[2025-09-13 23:56:07,442: INFO : common: created directory at path :artifacts/model_evaluation]
[2025-09-13 23:56:07,443: INFO : 1899718429: Model Evaluation Config: ModelEvaluationConfig(root_dir=WindowsPath('artifacts/model_evaluation'), test_data_path=WindowsPath('artifacts/data_transformation/test.csv'), model_path=WindowsPath('artifacts/model_trainer/model.joblib'), all_params=ConfigBox({'alpha': 0.2, 'l1_ratio': 0.1}), metric_file_name=WindowsPath('artifacts/model_evaluation/metrics.json'), target_column='quality', mlflow_uri='https://dagshub.com/bibhumlai/DSprojectusingMLOps.mlflow')]
[2025-09-13 23:56:07,446: INFO : 1304064896: Test data shape: (320, 12)]
[2025-09-13 23:56:07,447: INFO : 1304064896: Model: ElasticNet(alpha=0.2, l1_ratio=0.1, random_state=42)]
[2025-09-13 23:56:07,504: INFO : 1304064896: Elasticnet model (alpha=0.2, l1_ratio=0.1)]
[2025-09-13 23:56:07,505: INFO : 1304064896:   RMSE: 0.6929185588573523]
[2025-09-13 23:56:07,507: INFO : 1304064896:   MAE: 0.5543829927884041]
[2025-09-13 23:56:07,508: INFO : 1304064896:   R2: 0.2652917761622786]
[2025-09-13 23:56:07,510: INFO : common: json file saved at : artifacts\model_evaluation\metrics.json]
[2025-09-14 22:12:11,654: INFO : main: Welcome to custom logger DS]
[2025-09-14 22:12:11,654: INFO : main: >>>>>>>>>>>>>>> Stage Data Ingestion Stage Started  <<<<<<<<<<<<<]
[2025-09-14 22:12:11,663: INFO : common: yaml file: config\config.yaml loaded sucessfully]
[2025-09-14 22:12:11,670: INFO : common: yaml file: params.yaml loaded sucessfully]
[2025-09-14 22:12:11,679: INFO : common: yaml file: schema.yaml loaded sucessfully]
[2025-09-14 22:12:11,679: INFO : common: created directory at path :artifacts]
[2025-09-14 22:12:11,680: INFO : common: created directory at path :artifacts/data_ingestion]
[2025-09-14 22:12:11,680: INFO : data_ingestion: File already exists]
[2025-09-14 22:12:11,694: INFO : main: >>>>>> Stage Data Ingestion Stage Completed  <<<<<<<]
[2025-09-14 22:12:11,694: INFO : main: >>>>>>>>>>>>>>> Stage Data Validation  Stage Started  <<<<<<<<<<<<<]
[2025-09-14 22:12:11,697: INFO : common: yaml file: config\config.yaml loaded sucessfully]
[2025-09-14 22:12:11,698: INFO : common: yaml file: params.yaml loaded sucessfully]
[2025-09-14 22:12:11,700: INFO : common: yaml file: schema.yaml loaded sucessfully]
[2025-09-14 22:12:11,700: INFO : common: created directory at path :artifacts]
[2025-09-14 22:12:11,700: INFO : common: created directory at path :artifacts/data_validation]
[2025-09-14 22:12:11,722: INFO : main: >>>>>> Stage Data Validation  Stage Completed  <<<<<<<]
[2025-09-14 22:12:11,722: INFO : main: >>>>>>>>>>>>>>> Stage Data Transformation Stage Started  <<<<<<<<<<<<<]
[2025-09-14 22:12:11,733: INFO : common: yaml file: config\config.yaml loaded sucessfully]
[2025-09-14 22:12:11,734: INFO : common: yaml file: params.yaml loaded sucessfully]
[2025-09-14 22:12:11,736: INFO : common: yaml file: schema.yaml loaded sucessfully]
[2025-09-14 22:12:11,736: INFO : common: created directory at path :artifacts]
[2025-09-14 22:12:11,737: INFO : common: created directory at path :artifacts/data_transformation]
[2025-09-14 22:12:11,765: INFO : data_transformation: Train and Test data saved in artifacts\data_transformation]
[2025-09-14 22:12:11,765: INFO : data_transformation: (1279, 12)]
[2025-09-14 22:12:11,766: INFO : data_transformation: (320, 12)]
[2025-09-14 22:12:11,766: INFO : main: >>>>>> Stage Data Transformation Stage Completed  <<<<<<<]
[2025-09-14 22:12:11,766: INFO : main: >>>>>>>>>>>>>>> Stage Model Training Stage Started  <<<<<<<<<<<<<]
[2025-09-14 22:12:11,769: INFO : common: yaml file: config\config.yaml loaded sucessfully]
[2025-09-14 22:12:11,770: INFO : common: yaml file: params.yaml loaded sucessfully]
[2025-09-14 22:12:11,772: INFO : common: yaml file: schema.yaml loaded sucessfully]
[2025-09-14 22:12:11,773: INFO : common: created directory at path :artifacts]
[2025-09-14 22:12:11,773: INFO : model_train: Loading training and test data]
[2025-09-14 22:12:11,799: INFO : model_train: Splitting features and target]
[2025-09-14 22:12:11,801: INFO : model_train: Training the model]
[2025-09-14 22:12:11,804: INFO : model_train: Saving the model]
[2025-09-14 22:12:11,805: INFO : model_train: Model saved at artifacts\model_trainer\model.joblib]
[2025-09-14 22:12:11,806: INFO : model_train: Model training completed successfully]
[2025-09-14 22:12:11,806: INFO : main: >>>>>> Stage Model Training Stage Completed  <<<<<<<]
[2025-09-14 22:12:47,551: INFO : common: yaml file: config\config.yaml loaded sucessfully]
[2025-09-14 22:12:47,553: INFO : common: yaml file: params.yaml loaded sucessfully]
[2025-09-14 22:12:47,555: INFO : common: yaml file: schema.yaml loaded sucessfully]
[2025-09-14 22:12:47,557: INFO : common: created directory at path :artifacts]
[2025-09-14 22:12:47,558: INFO : common: created directory at path :artifacts/model_evaluation]
[2025-09-14 22:12:47,558: INFO : 1899718429: Model Evaluation Config: ModelEvaluationConfig(root_dir=WindowsPath('artifacts/model_evaluation'), test_data_path=WindowsPath('artifacts/data_transformation/test.csv'), model_path=WindowsPath('artifacts/model_trainer/model.joblib'), all_params=ConfigBox({'alpha': 0.2, 'l1_ratio': 0.1}), metric_file_name=WindowsPath('artifacts/model_evaluation/metrics.json'), target_column='quality', mlflow_uri='https://dagshub.com/bibhumlai/DSprojectusingMLOps.mlflow')]
[2025-09-14 22:12:47,563: INFO : 1304064896: Test data shape: (320, 12)]
[2025-09-14 22:12:47,647: INFO : 1304064896: Model: ElasticNet(alpha=0.2, l1_ratio=0.1, random_state=42)]
[2025-09-14 22:12:48,047: INFO : 1304064896: Elasticnet model (alpha=0.2, l1_ratio=0.1)]
[2025-09-14 22:12:48,050: INFO : 1304064896:   RMSE: 0.6929185588573523]
[2025-09-14 22:12:48,051: INFO : 1304064896:   MAE: 0.5543829927884041]
[2025-09-14 22:12:48,052: INFO : 1304064896:   R2: 0.2652917761622786]
[2025-09-14 22:12:48,054: INFO : common: json file saved at : artifacts\model_evaluation\metrics.json]
[2025-09-14 22:15:08,342: INFO : common: yaml file: config\config.yaml loaded sucessfully]
[2025-09-14 22:15:08,345: INFO : common: yaml file: params.yaml loaded sucessfully]
[2025-09-14 22:15:08,348: INFO : common: yaml file: schema.yaml loaded sucessfully]
[2025-09-14 22:15:08,349: INFO : common: created directory at path :artifacts]
[2025-09-14 22:15:08,350: INFO : common: created directory at path :artifacts/model_evaluation]
[2025-09-14 22:15:08,351: INFO : 1899718429: Model Evaluation Config: ModelEvaluationConfig(root_dir=WindowsPath('artifacts/model_evaluation'), test_data_path=WindowsPath('artifacts/data_transformation/test.csv'), model_path=WindowsPath('artifacts/model_trainer/model.joblib'), all_params=ConfigBox({'alpha': 0.2, 'l1_ratio': 0.1}), metric_file_name=WindowsPath('artifacts/model_evaluation/metrics.json'), target_column='quality', mlflow_uri='https://dagshub.com/bibhumlai/DSprojectusingMLOps.mlflow')]
[2025-09-14 22:15:08,355: INFO : 1304064896: Test data shape: (320, 12)]
[2025-09-14 22:15:08,432: INFO : 1304064896: Model: ElasticNet(alpha=0.2, l1_ratio=0.1, random_state=42)]
[2025-09-14 22:15:08,785: INFO : 1304064896: Elasticnet model (alpha=0.2, l1_ratio=0.1)]
[2025-09-14 22:15:08,786: INFO : 1304064896:   RMSE: 0.6929185588573523]
[2025-09-14 22:15:08,787: INFO : 1304064896:   MAE: 0.5543829927884041]
[2025-09-14 22:15:08,788: INFO : 1304064896:   R2: 0.2652917761622786]
[2025-09-14 22:15:08,789: INFO : common: json file saved at : artifacts\model_evaluation\metrics.json]
[2025-09-14 22:21:31,086: INFO : common: yaml file: config\config.yaml loaded sucessfully]
[2025-09-14 22:21:31,087: INFO : common: yaml file: params.yaml loaded sucessfully]
[2025-09-14 22:21:31,090: INFO : common: yaml file: schema.yaml loaded sucessfully]
[2025-09-14 22:21:31,091: INFO : common: created directory at path :artifacts]
[2025-09-14 22:21:31,092: INFO : common: created directory at path :artifacts/model_evaluation]
[2025-09-14 22:21:31,093: INFO : 1899718429: Model Evaluation Config: ModelEvaluationConfig(root_dir=WindowsPath('artifacts/model_evaluation'), test_data_path=WindowsPath('artifacts/data_transformation/test.csv'), model_path=WindowsPath('artifacts/model_trainer/model.joblib'), all_params=ConfigBox({'alpha': 0.2, 'l1_ratio': 0.1}), metric_file_name=WindowsPath('artifacts/model_evaluation/metrics.json'), target_column='quality', mlflow_uri='https://dagshub.com/bibhumlai/DSprojectusingMLOps.mlflow')]
[2025-09-14 22:21:31,096: INFO : 1388140217: Test data shape: (320, 12)]
[2025-09-14 22:21:31,098: INFO : 1388140217: Model: ElasticNet(alpha=0.2, l1_ratio=0.1, random_state=42)]
[2025-09-14 22:21:31,668: ERROR : 1899718429: API request to endpoint /api/2.0/mlflow/runs/create failed with error code 403 != 200. Response body: '']
Traceback (most recent call last):
  File "C:\Users\bibhu\AppData\Local\Temp\ipykernel_24980\1899718429.py", line 6, in <module>
    model_eval.log_into_mlflow()
    ~~~~~~~~~~~~~~~~~~~~~~~~~~^^
  File "C:\Users\bibhu\AppData\Local\Temp\ipykernel_24980\1388140217.py", line 24, in log_into_mlflow
    with mlflow.start_run():
         ~~~~~~~~~~~~~~~~^^
  File "d:\DE\ML OPs\DSusingMLOps\venv\Lib\site-packages\mlflow\tracking\fluent.py", line 474, in start_run
    active_run_obj = client.create_run(
        experiment_id=exp_id_for_run,
        tags=resolved_tags,
        run_name=run_name,
    )
  File "d:\DE\ML OPs\DSusingMLOps\venv\Lib\site-packages\mlflow\tracking\client.py", line 442, in create_run
    return self._tracking_client.create_run(experiment_id, start_time, tags, run_name)
           ~~~~~~~~~~~~~~~~~~~~~~~~~~~~~~~~^^^^^^^^^^^^^^^^^^^^^^^^^^^^^^^^^^^^^^^^^^^
  File "d:\DE\ML OPs\DSusingMLOps\venv\Lib\site-packages\mlflow\telemetry\track.py", line 29, in wrapper
    result = func(*args, **kwargs)
  File "d:\DE\ML OPs\DSusingMLOps\venv\Lib\site-packages\mlflow\tracking\_tracking_service\client.py", line 173, in create_run
    return self.store.create_run(
           ~~~~~~~~~~~~~~~~~~~~~^
        experiment_id=experiment_id,
        ^^^^^^^^^^^^^^^^^^^^^^^^^^^^
    ...<3 lines>...
        run_name=run_name,
        ^^^^^^^^^^^^^^^^^^
    )
    ^
  File "d:\DE\ML OPs\DSusingMLOps\venv\Lib\site-packages\mlflow\store\tracking\rest_store.py", line 271, in create_run
    response_proto = self._call_endpoint(CreateRun, req_body)
  File "d:\DE\ML OPs\DSusingMLOps\venv\Lib\site-packages\mlflow\store\tracking\rest_store.py", line 134, in _call_endpoint
    return call_endpoint(
        self.get_host_creds(),
    ...<4 lines>...
        retry_timeout_seconds=retry_timeout_seconds,
    )
  File "d:\DE\ML OPs\DSusingMLOps\venv\Lib\site-packages\mlflow\utils\rest_utils.py", line 554, in call_endpoint
    response = verify_rest_response(response, endpoint)
  File "d:\DE\ML OPs\DSusingMLOps\venv\Lib\site-packages\mlflow\utils\rest_utils.py", line 314, in verify_rest_response
    raise MlflowException(
    ...<2 lines>...
    )
mlflow.exceptions.MlflowException: API request to endpoint /api/2.0/mlflow/runs/create failed with error code 403 != 200. Response body: ''
[2025-09-14 22:21:44,223: INFO : common: yaml file: config\config.yaml loaded sucessfully]
[2025-09-14 22:21:44,225: INFO : common: yaml file: params.yaml loaded sucessfully]
[2025-09-14 22:21:44,228: INFO : common: yaml file: schema.yaml loaded sucessfully]
[2025-09-14 22:21:44,229: INFO : common: created directory at path :artifacts]
[2025-09-14 22:21:44,230: INFO : common: created directory at path :artifacts/model_evaluation]
[2025-09-14 22:21:44,231: INFO : 1899718429: Model Evaluation Config: ModelEvaluationConfig(root_dir=WindowsPath('artifacts/model_evaluation'), test_data_path=WindowsPath('artifacts/data_transformation/test.csv'), model_path=WindowsPath('artifacts/model_trainer/model.joblib'), all_params=ConfigBox({'alpha': 0.2, 'l1_ratio': 0.1}), metric_file_name=WindowsPath('artifacts/model_evaluation/metrics.json'), target_column='quality', mlflow_uri='https://dagshub.com/bibhumlai/DSprojectusingMLOps.mlflow')]
[2025-09-14 22:21:44,236: INFO : 1388140217: Test data shape: (320, 12)]
[2025-09-14 22:21:44,331: INFO : 1388140217: Model: ElasticNet(alpha=0.2, l1_ratio=0.1, random_state=42)]
[2025-09-14 22:21:45,178: ERROR : 1899718429: API request to endpoint /api/2.0/mlflow/runs/create failed with error code 403 != 200. Response body: '']
Traceback (most recent call last):
  File "C:\Users\bibhu\AppData\Local\Temp\ipykernel_1888\1899718429.py", line 6, in <module>
    model_eval.log_into_mlflow()
    ~~~~~~~~~~~~~~~~~~~~~~~~~~^^
  File "C:\Users\bibhu\AppData\Local\Temp\ipykernel_1888\1388140217.py", line 24, in log_into_mlflow
    with mlflow.start_run():
         ~~~~~~~~~~~~~~~~^^
  File "d:\DE\ML OPs\DSusingMLOps\venv\Lib\site-packages\mlflow\tracking\fluent.py", line 474, in start_run
    active_run_obj = client.create_run(
        experiment_id=exp_id_for_run,
        tags=resolved_tags,
        run_name=run_name,
    )
  File "d:\DE\ML OPs\DSusingMLOps\venv\Lib\site-packages\mlflow\tracking\client.py", line 442, in create_run
    return self._tracking_client.create_run(experiment_id, start_time, tags, run_name)
           ~~~~~~~~~~~~~~~~~~~~~~~~~~~~~~~~^^^^^^^^^^^^^^^^^^^^^^^^^^^^^^^^^^^^^^^^^^^
  File "d:\DE\ML OPs\DSusingMLOps\venv\Lib\site-packages\mlflow\telemetry\track.py", line 29, in wrapper
    result = func(*args, **kwargs)
  File "d:\DE\ML OPs\DSusingMLOps\venv\Lib\site-packages\mlflow\tracking\_tracking_service\client.py", line 173, in create_run
    return self.store.create_run(
           ~~~~~~~~~~~~~~~~~~~~~^
        experiment_id=experiment_id,
        ^^^^^^^^^^^^^^^^^^^^^^^^^^^^
    ...<3 lines>...
        run_name=run_name,
        ^^^^^^^^^^^^^^^^^^
    )
    ^
  File "d:\DE\ML OPs\DSusingMLOps\venv\Lib\site-packages\mlflow\store\tracking\rest_store.py", line 271, in create_run
    response_proto = self._call_endpoint(CreateRun, req_body)
  File "d:\DE\ML OPs\DSusingMLOps\venv\Lib\site-packages\mlflow\store\tracking\rest_store.py", line 134, in _call_endpoint
    return call_endpoint(
        self.get_host_creds(),
    ...<4 lines>...
        retry_timeout_seconds=retry_timeout_seconds,
    )
  File "d:\DE\ML OPs\DSusingMLOps\venv\Lib\site-packages\mlflow\utils\rest_utils.py", line 554, in call_endpoint
    response = verify_rest_response(response, endpoint)
  File "d:\DE\ML OPs\DSusingMLOps\venv\Lib\site-packages\mlflow\utils\rest_utils.py", line 314, in verify_rest_response
    raise MlflowException(
    ...<2 lines>...
    )
mlflow.exceptions.MlflowException: API request to endpoint /api/2.0/mlflow/runs/create failed with error code 403 != 200. Response body: ''
[2025-09-14 22:42:11,389: INFO : _client: HTTP Request: POST https://dagshub.com/login/oauth/middleman "HTTP/1.1 200 OK"]
[2025-09-14 22:42:11,974: INFO : _client: HTTP Request: POST https://dagshub.com/login/oauth/access_token "HTTP/1.1 200 OK"]
[2025-09-14 22:42:12,512: INFO : _client: HTTP Request: GET https://dagshub.com/api/v1/user "HTTP/1.1 200 OK"]
[2025-09-14 22:42:12,516: INFO : helpers: Accessing as bibhumlai]
[2025-09-14 22:42:13,050: INFO : _client: HTTP Request: GET https://dagshub.com/api/v1/repos/bibhumlai/DSprojectusingMLOps "HTTP/1.1 200 OK"]
[2025-09-14 22:42:13,990: INFO : _client: HTTP Request: GET https://dagshub.com/api/v1/user "HTTP/1.1 200 OK"]
[2025-09-14 22:42:13,994: INFO : helpers: Initialized MLflow to track repo "bibhumlai/DSprojectusingMLOps"]
[2025-09-14 22:42:13,996: INFO : helpers: Repository bibhumlai/DSprojectusingMLOps initialized!]
[2025-09-14 22:42:28,277: INFO : common: yaml file: config\config.yaml loaded sucessfully]
[2025-09-14 22:42:28,279: INFO : common: yaml file: params.yaml loaded sucessfully]
[2025-09-14 22:42:28,281: INFO : common: yaml file: schema.yaml loaded sucessfully]
[2025-09-14 22:42:28,283: INFO : common: created directory at path :artifacts]
[2025-09-14 22:42:28,285: INFO : common: created directory at path :artifacts/model_evaluation]
[2025-09-14 22:42:28,286: INFO : 1899718429: Model Evaluation Config: ModelEvaluationConfig(root_dir=WindowsPath('artifacts/model_evaluation'), test_data_path=WindowsPath('artifacts/data_transformation/test.csv'), model_path=WindowsPath('artifacts/model_trainer/model.joblib'), all_params=ConfigBox({'alpha': 0.2, 'l1_ratio': 0.1}), metric_file_name=WindowsPath('artifacts/model_evaluation/metrics.json'), target_column='quality', mlflow_uri='https://dagshub.com/bibhumlai/DSprojectusingMLOps.mlflow')]
[2025-09-14 22:42:28,289: INFO : 1304064896: Test data shape: (320, 12)]
[2025-09-14 22:42:28,291: INFO : 1304064896: Model: ElasticNet(alpha=0.2, l1_ratio=0.1, random_state=42)]
[2025-09-14 22:42:28,440: INFO : 1304064896: Elasticnet model (alpha=0.2, l1_ratio=0.1)]
[2025-09-14 22:42:28,441: INFO : 1304064896:   RMSE: 0.6929185588573523]
[2025-09-14 22:42:28,441: INFO : 1304064896:   MAE: 0.5543829927884041]
[2025-09-14 22:42:28,442: INFO : 1304064896:   R2: 0.2652917761622786]
[2025-09-14 22:42:28,443: INFO : common: json file saved at : artifacts\model_evaluation\metrics.json]
[2025-09-14 22:42:37,228: ERROR : 1899718429: INTERNAL_ERROR: Response: {'error': 'unsupported endpoint, please contact support@dagshub.com'}]
Traceback (most recent call last):
  File "C:\Users\bibhu\AppData\Local\Temp\ipykernel_1888\1899718429.py", line 6, in <module>
    model_eval.log_into_mlflow()
    ~~~~~~~~~~~~~~~~~~~~~~~~~~^^
  File "C:\Users\bibhu\AppData\Local\Temp\ipykernel_1888\1304064896.py", line 43, in log_into_mlflow
    mlflow.sklearn.log_model(model, "model", registered_model_name="ElasticnetWineModel")
    ~~~~~~~~~~~~~~~~~~~~~~~~^^^^^^^^^^^^^^^^^^^^^^^^^^^^^^^^^^^^^^^^^^^^^^^^^^^^^^^^^^^^^
  File "d:\DE\ML OPs\DSusingMLOps\venv\Lib\site-packages\mlflow\sklearn\__init__.py", line 426, in log_model
    return Model.log(
           ~~~~~~~~~^
        artifact_path=artifact_path,
        ^^^^^^^^^^^^^^^^^^^^^^^^^^^^
    ...<18 lines>...
        model_id=model_id,
        ^^^^^^^^^^^^^^^^^^
    )
    ^
  File "d:\DE\ML OPs\DSusingMLOps\venv\Lib\site-packages\mlflow\models\model.py", line 1169, in log
    model = _create_logged_model(
        # TODO: Update model name
    ...<7 lines>...
        flavor=flavor_name,
    )
  File "d:\DE\ML OPs\DSusingMLOps\venv\Lib\site-packages\mlflow\tracking\fluent.py", line 2305, in _create_logged_model
    return MlflowClient()._create_logged_model(
           ~~~~~~~~~~~~~~~~~~~~~~~~~~~~~~~~~~~^
        experiment_id=experiment_id,
        ^^^^^^^^^^^^^^^^^^^^^^^^^^^^
    ...<5 lines>...
        flavor=flavor,
        ^^^^^^^^^^^^^^
    )
    ^
  File "d:\DE\ML OPs\DSusingMLOps\venv\Lib\site-packages\mlflow\tracking\client.py", line 5394, in _create_logged_model
    return self._tracking_client.create_logged_model(
           ~~~~~~~~~~~~~~~~~~~~~~~~~~~~~~~~~~~~~~~~~^
        experiment_id, name, source_run_id, tags, params, model_type, flavor
        ^^^^^^^^^^^^^^^^^^^^^^^^^^^^^^^^^^^^^^^^^^^^^^^^^^^^^^^^^^^^^^^^^^^^
    )
    ^
  File "d:\DE\ML OPs\DSusingMLOps\venv\Lib\site-packages\mlflow\telemetry\track.py", line 29, in wrapper
    result = func(*args, **kwargs)
  File "d:\DE\ML OPs\DSusingMLOps\venv\Lib\site-packages\mlflow\tracking\_tracking_service\client.py", line 860, in create_logged_model
    return self.store.create_logged_model(
           ~~~~~~~~~~~~~~~~~~~~~~~~~~~~~~^
        experiment_id=experiment_id,
        ^^^^^^^^^^^^^^^^^^^^^^^^^^^^
    ...<8 lines>...
        model_type=model_type,
        ^^^^^^^^^^^^^^^^^^^^^^
    )
    ^
  File "d:\DE\ML OPs\DSusingMLOps\venv\Lib\site-packages\mlflow\store\tracking\rest_store.py", line 824, in create_logged_model
    response_proto = self._call_endpoint(CreateLoggedModel, req_body)
  File "d:\DE\ML OPs\DSusingMLOps\venv\Lib\site-packages\mlflow\store\tracking\rest_store.py", line 134, in _call_endpoint
    return call_endpoint(
        self.get_host_creds(),
    ...<4 lines>...
        retry_timeout_seconds=retry_timeout_seconds,
    )
  File "d:\DE\ML OPs\DSusingMLOps\venv\Lib\site-packages\mlflow\utils\rest_utils.py", line 554, in call_endpoint
    response = verify_rest_response(response, endpoint)
  File "d:\DE\ML OPs\DSusingMLOps\venv\Lib\site-packages\mlflow\utils\rest_utils.py", line 308, in verify_rest_response
    raise RestException(json.loads(response.text))
mlflow.exceptions.RestException: INTERNAL_ERROR: Response: {'error': 'unsupported endpoint, please contact support@dagshub.com'}
[2025-09-14 22:43:11,635: INFO : common: yaml file: config\config.yaml loaded sucessfully]
[2025-09-14 22:43:11,637: INFO : common: yaml file: params.yaml loaded sucessfully]
[2025-09-14 22:43:11,639: INFO : common: yaml file: schema.yaml loaded sucessfully]
[2025-09-14 22:43:11,640: INFO : common: created directory at path :artifacts]
[2025-09-14 22:43:11,641: INFO : common: created directory at path :artifacts/model_evaluation]
[2025-09-14 22:43:11,642: INFO : 1899718429: Model Evaluation Config: ModelEvaluationConfig(root_dir=WindowsPath('artifacts/model_evaluation'), test_data_path=WindowsPath('artifacts/data_transformation/test.csv'), model_path=WindowsPath('artifacts/model_trainer/model.joblib'), all_params=ConfigBox({'alpha': 0.2, 'l1_ratio': 0.1}), metric_file_name=WindowsPath('artifacts/model_evaluation/metrics.json'), target_column='quality', mlflow_uri='https://dagshub.com/bibhumlai/DSprojectusingMLOps.mlflow')]
[2025-09-14 22:43:11,645: INFO : 1304064896: Test data shape: (320, 12)]
[2025-09-14 22:43:11,647: INFO : 1304064896: Model: ElasticNet(alpha=0.2, l1_ratio=0.1, random_state=42)]
[2025-09-14 22:43:11,839: INFO : 1304064896: Elasticnet model (alpha=0.2, l1_ratio=0.1)]
[2025-09-14 22:43:11,840: INFO : 1304064896:   RMSE: 0.6929185588573523]
[2025-09-14 22:43:11,841: INFO : 1304064896:   MAE: 0.5543829927884041]
[2025-09-14 22:43:11,841: INFO : 1304064896:   R2: 0.2652917761622786]
[2025-09-14 22:43:11,842: INFO : common: json file saved at : artifacts\model_evaluation\metrics.json]
[2025-09-14 22:43:17,811: ERROR : 1899718429: INTERNAL_ERROR: Response: {'error': 'unsupported endpoint, please contact support@dagshub.com'}]
Traceback (most recent call last):
  File "C:\Users\bibhu\AppData\Local\Temp\ipykernel_1888\1899718429.py", line 6, in <module>
    model_eval.log_into_mlflow()
    ~~~~~~~~~~~~~~~~~~~~~~~~~~^^
  File "C:\Users\bibhu\AppData\Local\Temp\ipykernel_1888\1304064896.py", line 43, in log_into_mlflow
    mlflow.sklearn.log_model(model, "model", registered_model_name="ElasticnetWineModel")
    ~~~~~~~~~~~~~~~~~~~~~~~~^^^^^^^^^^^^^^^^^^^^^^^^^^^^^^^^^^^^^^^^^^^^^^^^^^^^^^^^^^^^^
  File "d:\DE\ML OPs\DSusingMLOps\venv\Lib\site-packages\mlflow\sklearn\__init__.py", line 426, in log_model
    return Model.log(
           ~~~~~~~~~^
        artifact_path=artifact_path,
        ^^^^^^^^^^^^^^^^^^^^^^^^^^^^
    ...<18 lines>...
        model_id=model_id,
        ^^^^^^^^^^^^^^^^^^
    )
    ^
  File "d:\DE\ML OPs\DSusingMLOps\venv\Lib\site-packages\mlflow\models\model.py", line 1169, in log
    model = _create_logged_model(
        # TODO: Update model name
    ...<7 lines>...
        flavor=flavor_name,
    )
  File "d:\DE\ML OPs\DSusingMLOps\venv\Lib\site-packages\mlflow\tracking\fluent.py", line 2305, in _create_logged_model
    return MlflowClient()._create_logged_model(
           ~~~~~~~~~~~~~~~~~~~~~~~~~~~~~~~~~~~^
        experiment_id=experiment_id,
        ^^^^^^^^^^^^^^^^^^^^^^^^^^^^
    ...<5 lines>...
        flavor=flavor,
        ^^^^^^^^^^^^^^
    )
    ^
  File "d:\DE\ML OPs\DSusingMLOps\venv\Lib\site-packages\mlflow\tracking\client.py", line 5394, in _create_logged_model
    return self._tracking_client.create_logged_model(
           ~~~~~~~~~~~~~~~~~~~~~~~~~~~~~~~~~~~~~~~~~^
        experiment_id, name, source_run_id, tags, params, model_type, flavor
        ^^^^^^^^^^^^^^^^^^^^^^^^^^^^^^^^^^^^^^^^^^^^^^^^^^^^^^^^^^^^^^^^^^^^
    )
    ^
  File "d:\DE\ML OPs\DSusingMLOps\venv\Lib\site-packages\mlflow\telemetry\track.py", line 29, in wrapper
    result = func(*args, **kwargs)
  File "d:\DE\ML OPs\DSusingMLOps\venv\Lib\site-packages\mlflow\tracking\_tracking_service\client.py", line 860, in create_logged_model
    return self.store.create_logged_model(
           ~~~~~~~~~~~~~~~~~~~~~~~~~~~~~~^
        experiment_id=experiment_id,
        ^^^^^^^^^^^^^^^^^^^^^^^^^^^^
    ...<8 lines>...
        model_type=model_type,
        ^^^^^^^^^^^^^^^^^^^^^^
    )
    ^
  File "d:\DE\ML OPs\DSusingMLOps\venv\Lib\site-packages\mlflow\store\tracking\rest_store.py", line 824, in create_logged_model
    response_proto = self._call_endpoint(CreateLoggedModel, req_body)
  File "d:\DE\ML OPs\DSusingMLOps\venv\Lib\site-packages\mlflow\store\tracking\rest_store.py", line 134, in _call_endpoint
    return call_endpoint(
        self.get_host_creds(),
    ...<4 lines>...
        retry_timeout_seconds=retry_timeout_seconds,
    )
  File "d:\DE\ML OPs\DSusingMLOps\venv\Lib\site-packages\mlflow\utils\rest_utils.py", line 554, in call_endpoint
    response = verify_rest_response(response, endpoint)
  File "d:\DE\ML OPs\DSusingMLOps\venv\Lib\site-packages\mlflow\utils\rest_utils.py", line 308, in verify_rest_response
    raise RestException(json.loads(response.text))
mlflow.exceptions.RestException: INTERNAL_ERROR: Response: {'error': 'unsupported endpoint, please contact support@dagshub.com'}
[2025-09-14 22:44:38,813: INFO : common: yaml file: config\config.yaml loaded sucessfully]
[2025-09-14 22:44:38,815: INFO : common: yaml file: params.yaml loaded sucessfully]
[2025-09-14 22:44:38,818: INFO : common: yaml file: schema.yaml loaded sucessfully]
[2025-09-14 22:44:38,819: INFO : common: created directory at path :artifacts]
[2025-09-14 22:44:38,820: INFO : common: created directory at path :artifacts/model_evaluation]
[2025-09-14 22:44:38,821: INFO : 1899718429: Model Evaluation Config: ModelEvaluationConfig(root_dir=WindowsPath('artifacts/model_evaluation'), test_data_path=WindowsPath('artifacts/data_transformation/test.csv'), model_path=WindowsPath('artifacts/model_trainer/model.joblib'), all_params=ConfigBox({'alpha': 0.2, 'l1_ratio': 0.1}), metric_file_name=WindowsPath('artifacts/model_evaluation/metrics.json'), target_column='quality', mlflow_uri='https://dagshub.com/bibhumlai/DSprojectusingMLOps.mlflow')]
[2025-09-14 22:44:38,825: INFO : 1976407236: Test data shape: (320, 12)]
[2025-09-14 22:44:38,827: INFO : 1976407236: Model: ElasticNet(alpha=0.2, l1_ratio=0.1, random_state=42)]
[2025-09-14 22:44:38,991: INFO : 1976407236: Elasticnet model (alpha=0.2, l1_ratio=0.1)]
[2025-09-14 22:44:38,992: INFO : 1976407236:   RMSE: 0.6929185588573523]
[2025-09-14 22:44:38,992: INFO : 1976407236:   MAE: 0.5543829927884041]
[2025-09-14 22:44:38,993: INFO : 1976407236:   R2: 0.2652917761622786]
[2025-09-14 22:44:38,994: INFO : common: json file saved at : artifacts\model_evaluation\metrics.json]
[2025-09-14 22:44:46,448: ERROR : 1899718429: INTERNAL_ERROR: Response: {'error': 'unsupported endpoint, please contact support@dagshub.com'}]
Traceback (most recent call last):
  File "C:\Users\bibhu\AppData\Local\Temp\ipykernel_1888\1899718429.py", line 6, in <module>
    model_eval.log_into_mlflow()
    ~~~~~~~~~~~~~~~~~~~~~~~~~~^^
  File "C:\Users\bibhu\AppData\Local\Temp\ipykernel_1888\1976407236.py", line 43, in log_into_mlflow
    mlflow.sklearn.log_model(model, "model")
    ~~~~~~~~~~~~~~~~~~~~~~~~^^^^^^^^^^^^^^^^
  File "d:\DE\ML OPs\DSusingMLOps\venv\Lib\site-packages\mlflow\sklearn\__init__.py", line 426, in log_model
    return Model.log(
           ~~~~~~~~~^
        artifact_path=artifact_path,
        ^^^^^^^^^^^^^^^^^^^^^^^^^^^^
    ...<18 lines>...
        model_id=model_id,
        ^^^^^^^^^^^^^^^^^^
    )
    ^
  File "d:\DE\ML OPs\DSusingMLOps\venv\Lib\site-packages\mlflow\models\model.py", line 1169, in log
    model = _create_logged_model(
        # TODO: Update model name
    ...<7 lines>...
        flavor=flavor_name,
    )
  File "d:\DE\ML OPs\DSusingMLOps\venv\Lib\site-packages\mlflow\tracking\fluent.py", line 2305, in _create_logged_model
    return MlflowClient()._create_logged_model(
           ~~~~~~~~~~~~~~~~~~~~~~~~~~~~~~~~~~~^
        experiment_id=experiment_id,
        ^^^^^^^^^^^^^^^^^^^^^^^^^^^^
    ...<5 lines>...
        flavor=flavor,
        ^^^^^^^^^^^^^^
    )
    ^
  File "d:\DE\ML OPs\DSusingMLOps\venv\Lib\site-packages\mlflow\tracking\client.py", line 5394, in _create_logged_model
    return self._tracking_client.create_logged_model(
           ~~~~~~~~~~~~~~~~~~~~~~~~~~~~~~~~~~~~~~~~~^
        experiment_id, name, source_run_id, tags, params, model_type, flavor
        ^^^^^^^^^^^^^^^^^^^^^^^^^^^^^^^^^^^^^^^^^^^^^^^^^^^^^^^^^^^^^^^^^^^^
    )
    ^
  File "d:\DE\ML OPs\DSusingMLOps\venv\Lib\site-packages\mlflow\telemetry\track.py", line 29, in wrapper
    result = func(*args, **kwargs)
  File "d:\DE\ML OPs\DSusingMLOps\venv\Lib\site-packages\mlflow\tracking\_tracking_service\client.py", line 860, in create_logged_model
    return self.store.create_logged_model(
           ~~~~~~~~~~~~~~~~~~~~~~~~~~~~~~^
        experiment_id=experiment_id,
        ^^^^^^^^^^^^^^^^^^^^^^^^^^^^
    ...<8 lines>...
        model_type=model_type,
        ^^^^^^^^^^^^^^^^^^^^^^
    )
    ^
  File "d:\DE\ML OPs\DSusingMLOps\venv\Lib\site-packages\mlflow\store\tracking\rest_store.py", line 824, in create_logged_model
    response_proto = self._call_endpoint(CreateLoggedModel, req_body)
  File "d:\DE\ML OPs\DSusingMLOps\venv\Lib\site-packages\mlflow\store\tracking\rest_store.py", line 134, in _call_endpoint
    return call_endpoint(
        self.get_host_creds(),
    ...<4 lines>...
        retry_timeout_seconds=retry_timeout_seconds,
    )
  File "d:\DE\ML OPs\DSusingMLOps\venv\Lib\site-packages\mlflow\utils\rest_utils.py", line 554, in call_endpoint
    response = verify_rest_response(response, endpoint)
  File "d:\DE\ML OPs\DSusingMLOps\venv\Lib\site-packages\mlflow\utils\rest_utils.py", line 308, in verify_rest_response
    raise RestException(json.loads(response.text))
mlflow.exceptions.RestException: INTERNAL_ERROR: Response: {'error': 'unsupported endpoint, please contact support@dagshub.com'}
[2025-09-14 22:45:45,355: INFO : common: yaml file: config\config.yaml loaded sucessfully]
[2025-09-14 22:45:45,357: INFO : common: yaml file: params.yaml loaded sucessfully]
[2025-09-14 22:45:45,360: INFO : common: yaml file: schema.yaml loaded sucessfully]
[2025-09-14 22:45:45,362: INFO : common: created directory at path :artifacts]
[2025-09-14 22:45:45,363: INFO : common: created directory at path :artifacts/model_evaluation]
[2025-09-14 22:45:45,364: INFO : 1899718429: Model Evaluation Config: ModelEvaluationConfig(root_dir=WindowsPath('artifacts/model_evaluation'), test_data_path=WindowsPath('artifacts/data_transformation/test.csv'), model_path=WindowsPath('artifacts/model_trainer/model.joblib'), all_params=ConfigBox({'alpha': 0.2, 'l1_ratio': 0.1}), metric_file_name=WindowsPath('artifacts/model_evaluation/metrics.json'), target_column='quality', mlflow_uri='https://dagshub.com/bibhumlai/DSprojectusingMLOps.mlflow')]
[2025-09-14 22:45:45,369: INFO : 1976407236: Test data shape: (320, 12)]
[2025-09-14 22:45:45,371: INFO : 1976407236: Model: ElasticNet(alpha=0.2, l1_ratio=0.1, random_state=42)]
[2025-09-14 22:45:45,537: INFO : 1976407236: Elasticnet model (alpha=0.2, l1_ratio=0.1)]
[2025-09-14 22:45:45,538: INFO : 1976407236:   RMSE: 0.6929185588573523]
[2025-09-14 22:45:45,539: INFO : 1976407236:   MAE: 0.5543829927884041]
[2025-09-14 22:45:45,539: INFO : 1976407236:   R2: 0.2652917761622786]
[2025-09-14 22:45:45,540: INFO : common: json file saved at : artifacts\model_evaluation\metrics.json]
[2025-09-14 22:45:51,531: ERROR : 1899718429: INTERNAL_ERROR: Response: {'error': 'unsupported endpoint, please contact support@dagshub.com'}]
Traceback (most recent call last):
  File "C:\Users\bibhu\AppData\Local\Temp\ipykernel_1888\1899718429.py", line 6, in <module>
    model_eval.log_into_mlflow()
    ~~~~~~~~~~~~~~~~~~~~~~~~~~^^
  File "C:\Users\bibhu\AppData\Local\Temp\ipykernel_1888\1976407236.py", line 43, in log_into_mlflow
    mlflow.sklearn.log_model(model, "model")
    ~~~~~~~~~~~~~~~~~~~~~~~~^^^^^^^^^^^^^^^^
  File "d:\DE\ML OPs\DSusingMLOps\venv\Lib\site-packages\mlflow\sklearn\__init__.py", line 426, in log_model
    return Model.log(
           ~~~~~~~~~^
        artifact_path=artifact_path,
        ^^^^^^^^^^^^^^^^^^^^^^^^^^^^
    ...<18 lines>...
        model_id=model_id,
        ^^^^^^^^^^^^^^^^^^
    )
    ^
  File "d:\DE\ML OPs\DSusingMLOps\venv\Lib\site-packages\mlflow\models\model.py", line 1169, in log
    model = _create_logged_model(
        # TODO: Update model name
    ...<7 lines>...
        flavor=flavor_name,
    )
  File "d:\DE\ML OPs\DSusingMLOps\venv\Lib\site-packages\mlflow\tracking\fluent.py", line 2305, in _create_logged_model
    return MlflowClient()._create_logged_model(
           ~~~~~~~~~~~~~~~~~~~~~~~~~~~~~~~~~~~^
        experiment_id=experiment_id,
        ^^^^^^^^^^^^^^^^^^^^^^^^^^^^
    ...<5 lines>...
        flavor=flavor,
        ^^^^^^^^^^^^^^
    )
    ^
  File "d:\DE\ML OPs\DSusingMLOps\venv\Lib\site-packages\mlflow\tracking\client.py", line 5394, in _create_logged_model
    return self._tracking_client.create_logged_model(
           ~~~~~~~~~~~~~~~~~~~~~~~~~~~~~~~~~~~~~~~~~^
        experiment_id, name, source_run_id, tags, params, model_type, flavor
        ^^^^^^^^^^^^^^^^^^^^^^^^^^^^^^^^^^^^^^^^^^^^^^^^^^^^^^^^^^^^^^^^^^^^
    )
    ^
  File "d:\DE\ML OPs\DSusingMLOps\venv\Lib\site-packages\mlflow\telemetry\track.py", line 29, in wrapper
    result = func(*args, **kwargs)
  File "d:\DE\ML OPs\DSusingMLOps\venv\Lib\site-packages\mlflow\tracking\_tracking_service\client.py", line 860, in create_logged_model
    return self.store.create_logged_model(
           ~~~~~~~~~~~~~~~~~~~~~~~~~~~~~~^
        experiment_id=experiment_id,
        ^^^^^^^^^^^^^^^^^^^^^^^^^^^^
    ...<8 lines>...
        model_type=model_type,
        ^^^^^^^^^^^^^^^^^^^^^^
    )
    ^
  File "d:\DE\ML OPs\DSusingMLOps\venv\Lib\site-packages\mlflow\store\tracking\rest_store.py", line 824, in create_logged_model
    response_proto = self._call_endpoint(CreateLoggedModel, req_body)
  File "d:\DE\ML OPs\DSusingMLOps\venv\Lib\site-packages\mlflow\store\tracking\rest_store.py", line 134, in _call_endpoint
    return call_endpoint(
        self.get_host_creds(),
    ...<4 lines>...
        retry_timeout_seconds=retry_timeout_seconds,
    )
  File "d:\DE\ML OPs\DSusingMLOps\venv\Lib\site-packages\mlflow\utils\rest_utils.py", line 554, in call_endpoint
    response = verify_rest_response(response, endpoint)
  File "d:\DE\ML OPs\DSusingMLOps\venv\Lib\site-packages\mlflow\utils\rest_utils.py", line 308, in verify_rest_response
    raise RestException(json.loads(response.text))
mlflow.exceptions.RestException: INTERNAL_ERROR: Response: {'error': 'unsupported endpoint, please contact support@dagshub.com'}
[2025-09-14 22:48:34,699: INFO : common: yaml file: config\config.yaml loaded sucessfully]
[2025-09-14 22:48:34,701: INFO : common: yaml file: params.yaml loaded sucessfully]
[2025-09-14 22:48:34,704: INFO : common: yaml file: schema.yaml loaded sucessfully]
[2025-09-14 22:48:34,705: INFO : common: created directory at path :artifacts]
[2025-09-14 22:48:34,706: INFO : common: created directory at path :artifacts/model_evaluation]
[2025-09-14 22:48:34,707: INFO : 1899718429: Model Evaluation Config: ModelEvaluationConfig(root_dir=WindowsPath('artifacts/model_evaluation'), test_data_path=WindowsPath('artifacts/data_transformation/test.csv'), model_path=WindowsPath('artifacts/model_trainer/model.joblib'), all_params=ConfigBox({'alpha': 0.2, 'l1_ratio': 0.1}), metric_file_name=WindowsPath('artifacts/model_evaluation/metrics.json'), target_column='quality', mlflow_uri='https://dagshub.com/bibhumlai/DSprojectusingMLOps.mlflow')]
[2025-09-14 22:48:34,711: INFO : 652575384: Test data shape: (320, 12)]
[2025-09-14 22:48:34,713: INFO : 652575384: Model: ElasticNet(alpha=0.2, l1_ratio=0.1, random_state=42)]
[2025-09-14 22:48:34,876: INFO : 652575384: Elasticnet model (alpha=0.2, l1_ratio=0.1)]
[2025-09-14 22:48:34,877: INFO : 652575384:   RMSE: 0.6929185588573523]
[2025-09-14 22:48:34,878: INFO : 652575384:   MAE: 0.5543829927884041]
[2025-09-14 22:48:34,879: INFO : 652575384:   R2: 0.2652917761622786]
[2025-09-14 22:48:34,880: INFO : common: json file saved at : artifacts\model_evaluation\metrics.json]
[2025-09-14 23:10:44,557: INFO : main: Welcome to custom logger DS]
[2025-09-14 23:10:44,557: INFO : main: >>>>>>>>>>>>>>> Stage Data Ingestion Stage Started  <<<<<<<<<<<<<]
[2025-09-14 23:10:44,560: INFO : common: yaml file: config\config.yaml loaded sucessfully]
[2025-09-14 23:10:44,561: INFO : common: yaml file: params.yaml loaded sucessfully]
[2025-09-14 23:10:44,563: INFO : common: yaml file: schema.yaml loaded sucessfully]
[2025-09-14 23:10:44,563: INFO : common: created directory at path :artifacts]
[2025-09-14 23:10:44,564: INFO : common: created directory at path :artifacts/data_ingestion]
[2025-09-14 23:10:44,564: INFO : data_ingestion: File already exists]
[2025-09-14 23:10:44,565: INFO : main: >>>>>> Stage Data Ingestion Stage Completed  <<<<<<<]
[2025-09-14 23:10:44,565: INFO : main: >>>>>>>>>>>>>>> Stage Data Validation  Stage Started  <<<<<<<<<<<<<]
[2025-09-14 23:10:44,568: INFO : common: yaml file: config\config.yaml loaded sucessfully]
[2025-09-14 23:10:44,569: INFO : common: yaml file: params.yaml loaded sucessfully]
[2025-09-14 23:10:44,571: INFO : common: yaml file: schema.yaml loaded sucessfully]
[2025-09-14 23:10:44,571: INFO : common: created directory at path :artifacts]
[2025-09-14 23:10:44,572: INFO : common: created directory at path :artifacts/data_validation]
[2025-09-14 23:10:44,599: INFO : main: >>>>>> Stage Data Validation  Stage Completed  <<<<<<<]
[2025-09-14 23:10:44,599: INFO : main: >>>>>>>>>>>>>>> Stage Data Transformation Stage Started  <<<<<<<<<<<<<]
[2025-09-14 23:10:44,612: INFO : common: yaml file: config\config.yaml loaded sucessfully]
[2025-09-14 23:10:44,613: INFO : common: yaml file: params.yaml loaded sucessfully]
[2025-09-14 23:10:44,615: INFO : common: yaml file: schema.yaml loaded sucessfully]
[2025-09-14 23:10:44,615: INFO : common: created directory at path :artifacts]
[2025-09-14 23:10:44,616: INFO : common: created directory at path :artifacts/data_transformation]
[2025-09-14 23:10:44,642: INFO : data_transformation: Train and Test data saved in artifacts\data_transformation]
[2025-09-14 23:10:44,643: INFO : data_transformation: (1279, 12)]
[2025-09-14 23:10:44,643: INFO : data_transformation: (320, 12)]
[2025-09-14 23:10:44,644: INFO : main: >>>>>> Stage Data Transformation Stage Completed  <<<<<<<]
[2025-09-14 23:10:44,644: INFO : main: >>>>>>>>>>>>>>> Stage Model Training Stage Started  <<<<<<<<<<<<<]
[2025-09-14 23:10:44,649: INFO : common: yaml file: config\config.yaml loaded sucessfully]
[2025-09-14 23:10:44,650: INFO : common: yaml file: params.yaml loaded sucessfully]
[2025-09-14 23:10:44,654: INFO : common: yaml file: schema.yaml loaded sucessfully]
[2025-09-14 23:10:44,655: INFO : common: created directory at path :artifacts]
[2025-09-14 23:10:44,655: INFO : model_train: Loading training and test data]
[2025-09-14 23:10:44,694: INFO : model_train: Splitting features and target]
[2025-09-14 23:10:44,696: INFO : model_train: Training the model]
[2025-09-14 23:10:44,700: INFO : model_train: Saving the model]
[2025-09-14 23:10:44,703: INFO : model_train: Model saved at artifacts\model_trainer\model.joblib]
[2025-09-14 23:10:44,703: INFO : model_train: Model training completed successfully]
[2025-09-14 23:10:44,704: INFO : main: >>>>>> Stage Model Training Stage Completed  <<<<<<<]
[2025-09-14 23:10:44,704: INFO : main: >>>>>>>>>>>>>>> Stage Model Evaluation  Stage Started  <<<<<<<<<<<<<]
[2025-09-14 23:10:44,708: INFO : common: yaml file: config\config.yaml loaded sucessfully]
[2025-09-14 23:10:44,710: INFO : common: yaml file: params.yaml loaded sucessfully]
[2025-09-14 23:10:44,713: INFO : common: yaml file: schema.yaml loaded sucessfully]
[2025-09-14 23:10:44,714: INFO : common: created directory at path :artifacts]
[2025-09-14 23:10:44,715: INFO : common: created directory at path :artifacts/model_evaluation]
[2025-09-14 23:10:44,716: INFO : model_evaluation_pipeline: Model Evaluation Config: ModelEvaluationConfig(root_dir=WindowsPath('artifacts/model_evaluation'), test_data_path=WindowsPath('artifacts/data_transformation/test.csv'), model_path=WindowsPath('artifacts/model_trainer/model.joblib'), all_params=ConfigBox({'alpha': 0.2, 'l1_ratio': 0.1}), metric_file_name=WindowsPath('artifacts/model_evaluation/metrics.json'), target_column='quality', mlflow_uri='https://dagshub.com/bibhumlai/DSprojectusingMLOps.mlflow')]
[2025-09-14 23:10:44,718: INFO : model_evaluation: Test data shape: (320, 12)]
[2025-09-14 23:10:44,721: INFO : model_evaluation: Model: ElasticNet(alpha=0.2, l1_ratio=0.1, random_state=42)]
[2025-09-14 23:10:45,655: INFO : model_evaluation: Elasticnet model (alpha=0.2, l1_ratio=0.1)]
[2025-09-14 23:10:45,656: INFO : model_evaluation:   RMSE: 0.6929185588573523]
[2025-09-14 23:10:45,656: INFO : model_evaluation:   MAE: 0.5543829927884041]
[2025-09-14 23:10:45,656: INFO : model_evaluation:   R2: 0.2652917761622786]
[2025-09-14 23:10:45,656: INFO : common: json file saved at : artifacts\model_evaluation\metrics.json]
[2025-09-14 23:10:45,717: ERROR : model_evaluation_pipeline: Path 'artifacts\model_evaluation\model' already exists and is not empty]
Traceback (most recent call last):
  File "D:\DE\ML OPs\DSusingMLOps\src\datascience\pipeline\model_evaluation_pipeline.py", line 18, in initiate_model_Evaluation
    model_eval.log_into_mlflow()
    ~~~~~~~~~~~~~~~~~~~~~~~~~~^^
  File "D:\DE\ML OPs\DSusingMLOps\src\datascience\components\model_evaluation.py", line 56, in log_into_mlflow
    mlflow.sklearn.save_model(model, path=str(model_path))
    ~~~~~~~~~~~~~~~~~~~~~~~~~^^^^^^^^^^^^^^^^^^^^^^^^^^^^^
  File "D:\DE\ML OPs\DSusingMLOps\venv\Lib\site-packages\mlflow\sklearn\__init__.py", line 245, in save_model
    _validate_and_prepare_target_save_path(path)
    ~~~~~~~~~~~~~~~~~~~~~~~~~~~~~~~~~~~~~~^^^^^^
  File "D:\DE\ML OPs\DSusingMLOps\venv\Lib\site-packages\mlflow\utils\model_utils.py", line 271, in _validate_and_prepare_target_save_path
    raise MlflowException(
    ...<2 lines>...
    )
mlflow.exceptions.MlflowException: Path 'artifacts\model_evaluation\model' already exists and is not empty
[2025-09-14 23:10:45,720: ERROR : main: Path 'artifacts\model_evaluation\model' already exists and is not empty]
Traceback (most recent call last):
  File "D:\DE\ML OPs\DSusingMLOps\main.py", line 58, in <module>
    obj.initiate_model_Evaluation()
    ~~~~~~~~~~~~~~~~~~~~~~~~~~~~~^^
  File "D:\DE\ML OPs\DSusingMLOps\src\datascience\pipeline\model_evaluation_pipeline.py", line 21, in initiate_model_Evaluation
    raise e
  File "D:\DE\ML OPs\DSusingMLOps\src\datascience\pipeline\model_evaluation_pipeline.py", line 18, in initiate_model_Evaluation
    model_eval.log_into_mlflow()
    ~~~~~~~~~~~~~~~~~~~~~~~~~~^^
  File "D:\DE\ML OPs\DSusingMLOps\src\datascience\components\model_evaluation.py", line 56, in log_into_mlflow
    mlflow.sklearn.save_model(model, path=str(model_path))
    ~~~~~~~~~~~~~~~~~~~~~~~~~^^^^^^^^^^^^^^^^^^^^^^^^^^^^^
  File "D:\DE\ML OPs\DSusingMLOps\venv\Lib\site-packages\mlflow\sklearn\__init__.py", line 245, in save_model
    _validate_and_prepare_target_save_path(path)
    ~~~~~~~~~~~~~~~~~~~~~~~~~~~~~~~~~~~~~~^^^^^^
  File "D:\DE\ML OPs\DSusingMLOps\venv\Lib\site-packages\mlflow\utils\model_utils.py", line 271, in _validate_and_prepare_target_save_path
    raise MlflowException(
    ...<2 lines>...
    )
mlflow.exceptions.MlflowException: Path 'artifacts\model_evaluation\model' already exists and is not empty
[2025-09-14 23:11:25,237: INFO : main: Welcome to custom logger DS]
[2025-09-14 23:11:25,238: INFO : main: >>>>>>>>>>>>>>> Stage Data Ingestion Stage Started  <<<<<<<<<<<<<]
[2025-09-14 23:11:25,241: INFO : common: yaml file: config\config.yaml loaded sucessfully]
[2025-09-14 23:11:25,242: INFO : common: yaml file: params.yaml loaded sucessfully]
[2025-09-14 23:11:25,244: INFO : common: yaml file: schema.yaml loaded sucessfully]
[2025-09-14 23:11:25,246: INFO : common: created directory at path :artifacts]
[2025-09-14 23:11:25,246: INFO : common: created directory at path :artifacts/data_ingestion]
[2025-09-14 23:11:25,246: INFO : data_ingestion: File already exists]
[2025-09-14 23:11:25,249: INFO : main: >>>>>> Stage Data Ingestion Stage Completed  <<<<<<<]
[2025-09-14 23:11:25,249: INFO : main: >>>>>>>>>>>>>>> Stage Data Validation  Stage Started  <<<<<<<<<<<<<]
[2025-09-14 23:11:25,255: INFO : common: yaml file: config\config.yaml loaded sucessfully]
[2025-09-14 23:11:25,257: INFO : common: yaml file: params.yaml loaded sucessfully]
[2025-09-14 23:11:25,260: INFO : common: yaml file: schema.yaml loaded sucessfully]
[2025-09-14 23:11:25,261: INFO : common: created directory at path :artifacts]
[2025-09-14 23:11:25,262: INFO : common: created directory at path :artifacts/data_validation]
[2025-09-14 23:11:25,289: INFO : main: >>>>>> Stage Data Validation  Stage Completed  <<<<<<<]
[2025-09-14 23:11:25,289: INFO : main: >>>>>>>>>>>>>>> Stage Data Transformation Stage Started  <<<<<<<<<<<<<]
[2025-09-14 23:11:25,295: INFO : common: yaml file: config\config.yaml loaded sucessfully]
[2025-09-14 23:11:25,297: INFO : common: yaml file: params.yaml loaded sucessfully]
[2025-09-14 23:11:25,302: INFO : common: yaml file: schema.yaml loaded sucessfully]
[2025-09-14 23:11:25,304: INFO : common: created directory at path :artifacts]
[2025-09-14 23:11:25,306: INFO : common: created directory at path :artifacts/data_transformation]
[2025-09-14 23:11:25,344: INFO : data_transformation: Train and Test data saved in artifacts\data_transformation]
[2025-09-14 23:11:25,345: INFO : data_transformation: (1279, 12)]
[2025-09-14 23:11:25,345: INFO : data_transformation: (320, 12)]
[2025-09-14 23:11:25,345: INFO : main: >>>>>> Stage Data Transformation Stage Completed  <<<<<<<]
[2025-09-14 23:11:25,346: INFO : main: >>>>>>>>>>>>>>> Stage Model Training Stage Started  <<<<<<<<<<<<<]
[2025-09-14 23:11:25,352: INFO : common: yaml file: config\config.yaml loaded sucessfully]
[2025-09-14 23:11:25,354: INFO : common: yaml file: params.yaml loaded sucessfully]
[2025-09-14 23:11:25,357: INFO : common: yaml file: schema.yaml loaded sucessfully]
[2025-09-14 23:11:25,358: INFO : common: created directory at path :artifacts]
[2025-09-14 23:11:25,359: INFO : model_train: Loading training and test data]
[2025-09-14 23:11:25,406: INFO : model_train: Splitting features and target]
[2025-09-14 23:11:25,409: INFO : model_train: Training the model]
[2025-09-14 23:11:25,415: INFO : model_train: Saving the model]
[2025-09-14 23:11:25,421: INFO : model_train: Model saved at artifacts\model_trainer\model.joblib]
[2025-09-14 23:11:25,421: INFO : model_train: Model training completed successfully]
[2025-09-14 23:11:25,422: INFO : main: >>>>>> Stage Model Training Stage Completed  <<<<<<<]
[2025-09-14 23:11:25,422: INFO : main: >>>>>>>>>>>>>>> Stage Model Evaluation  Stage Started  <<<<<<<<<<<<<]
[2025-09-14 23:11:25,428: INFO : common: yaml file: config\config.yaml loaded sucessfully]
[2025-09-14 23:11:25,430: INFO : common: yaml file: params.yaml loaded sucessfully]
[2025-09-14 23:11:25,435: INFO : common: yaml file: schema.yaml loaded sucessfully]
[2025-09-14 23:11:25,436: INFO : common: created directory at path :artifacts]
[2025-09-14 23:11:25,437: INFO : common: created directory at path :artifacts/model_evaluation]
[2025-09-14 23:11:25,439: INFO : model_evaluation_pipeline: Model Evaluation Config: ModelEvaluationConfig(root_dir=WindowsPath('artifacts/model_evaluation'), test_data_path=WindowsPath('artifacts/data_transformation/test.csv'), model_path=WindowsPath('artifacts/model_trainer/model.joblib'), all_params=ConfigBox({'alpha': 0.2, 'l1_ratio': 0.1}), metric_file_name=WindowsPath('artifacts/model_evaluation/metrics.json'), target_column='quality', mlflow_uri='https://dagshub.com/bibhumlai/DSprojectusingMLOps.mlflow')]
[2025-09-14 23:11:25,442: INFO : model_evaluation: Test data shape: (320, 12)]
[2025-09-14 23:11:25,448: INFO : model_evaluation: Model: ElasticNet(alpha=0.2, l1_ratio=0.1, random_state=42)]
[2025-09-14 23:11:26,415: INFO : model_evaluation: Elasticnet model (alpha=0.2, l1_ratio=0.1)]
[2025-09-14 23:11:26,415: INFO : model_evaluation:   RMSE: 0.6929185588573523]
[2025-09-14 23:11:26,416: INFO : model_evaluation:   MAE: 0.5543829927884041]
[2025-09-14 23:11:26,416: INFO : model_evaluation:   R2: 0.2652917761622786]
[2025-09-14 23:11:26,416: INFO : common: json file saved at : artifacts\model_evaluation\metrics.json]
[2025-09-14 23:11:34,304: INFO : main: >>>>>> Stage Model Evaluation  Stage Completed  <<<<<<<]
